return {
  {["x"] = 0, ["y"] = 0, ["z"] = 0, ["name"] = "default:cobble"},
  {["x"] = 0, ["y"] = 0, ["z"] = 1, ["name"] = "default:cobble"},
  {["x"] = 0, ["y"] = 0, ["z"] = 2, ["name"] = "default:cobble"},
  {["x"] = 0, ["y"] = 0, ["z"] = 3, ["name"] = "default:cobble"},
  {["x"] = 0, ["y"] = 0, ["z"] = 4, ["name"] = "default:cobble"},
  {["x"] = 0, ["y"] = 0, ["z"] = 5, ["name"] = "default:cobble"},
  {["x"] = 1, ["y"] = 0, ["z"] = 0, ["name"] = "default:cobble"},
  {["x"] = 1, ["y"] = 0, ["z"] = 1, ["name"] = "default:cobble"},
  {["x"] = 1, ["y"] = 0, ["z"] = 2, ["name"] = "default:cobble"},
  {["x"] = 1, ["y"] = 0, ["z"] = 3, ["name"] = "default:cobble"},
  {["x"] = 1, ["y"] = 0, ["z"] = 4, ["name"] = "default:cobble"},
  {["x"] = 1, ["y"] = 0, ["z"] = 5, ["name"] = "default:cobble"},
  {["x"] = 2, ["y"] = 0, ["z"] = 0, ["name"] = "default:cobble"},
  {["x"] = 2, ["y"] = 0, ["z"] = 1, ["name"] = "default:cobble"},
  {["x"] = 2, ["y"] = 0, ["z"] = 2, ["name"] = "default:cobble"},
  {["x"] = 2, ["y"] = 0, ["z"] = 3, ["name"] = "default:cobble"},
  {["x"] = 2, ["y"] = 0, ["z"] = 4, ["name"] = "default:cobble"},
  {["x"] = 2, ["y"] = 0, ["z"] = 5, ["name"] = "default:cobble"},
  {["x"] = 3, ["y"] = 0, ["z"] = 0, ["name"] = "default:cobble"},
  {["x"] = 3, ["y"] = 0, ["z"] = 1, ["name"] = "default:cobble"},
  {["x"] = 3, ["y"] = 0, ["z"] = 2, ["name"] = "default:cobble"},
  {["x"] = 3, ["y"] = 0, ["z"] = 3, ["name"] = "default:cobble"},
  {["x"] = 3, ["y"] = 0, ["z"] = 4, ["name"] = "default:cobble"},
  {["x"] = 3, ["y"] = 0, ["z"] = 5, ["name"] = "default:cobble"},
  {["x"] = 4, ["y"] = 0, ["z"] = 0, ["name"] = "default:cobble"},
  {["x"] = 4, ["y"] = 0, ["z"] = 1, ["name"] = "default:cobble"},
  {["x"] = 4, ["y"] = 0, ["z"] = 2, ["name"] = "default:cobble"},
  {["x"] = 4, ["y"] = 0, ["z"] = 3, ["name"] = "default:cobble"},
  {["x"] = 4, ["y"] = 0, ["z"] = 4, ["name"] = "default:cobble"},
  {["x"] = 4, ["y"] = 0, ["z"] = 5, ["name"] = "default:cobble"},
  {["x"] = 5, ["y"] = 0, ["z"] = 0, ["name"] = "default:cobble"},
  {["x"] = 5, ["y"] = 0, ["z"] = 1, ["name"] = "default:cobble"},
  {["x"] = 5, ["y"] = 0, ["z"] = 2, ["name"] = "default:cobble"},
  {["x"] = 5, ["y"] = 0, ["z"] = 3, ["name"] = "default:cobble"},
  {["x"] = 5, ["y"] = 0, ["z"] = 4, ["name"] = "default:cobble"},
  {["x"] = 5, ["y"] = 0, ["z"] = 5, ["name"] = "default:cobble"},
  {["x"] = 6, ["y"] = 0, ["z"] = 0, ["name"] = "default:cobble"},
  {["x"] = 6, ["y"] = 0, ["z"] = 1, ["name"] = "default:cobble"},
  {["x"] = 6, ["y"] = 0, ["z"] = 2, ["name"] = "default:cobble"},
  {["x"] = 6, ["y"] = 0, ["z"] = 3, ["name"] = "default:cobble"},
  {["x"] = 6, ["y"] = 0, ["z"] = 4, ["name"] = "default:cobble"},
  {["x"] = 6, ["y"] = 0, ["z"] = 5, ["name"] = "default:cobble"},
  {["x"] = 0, ["y"] = 1, ["z"] = 0, ["name"] = "default:stone"},
  {["x"] = 0, ["y"] = 1, ["z"] = 1, ["name"] = "default:stone"},
  {["x"] = 0, ["y"] = 1, ["z"] = 2, ["name"] = "default:stone"},
  {["x"] = 0, ["y"] = 1, ["z"] = 3, ["name"] = "default:stone"},
  {["x"] = 0, ["y"] = 1, ["z"] = 4, ["name"] = "default:stone"},
  {["x"] = 0, ["y"] = 1, ["z"] = 5, ["name"] = "default:stone"},
  {["x"] = 1, ["y"] = 1, ["z"] = 0, ["name"] = "default:stone"},
  {["x"] = 1, ["y"] = 1, ["z"] = 4, ["name"] = "default:torch"},
  {["x"] = 1, ["y"] = 1, ["z"] = 5, ["name"] = "default:stone"},
  {["x"] = 2, ["y"] = 1, ["z"] = 0, ["name"] = "default:stone"},
  {["x"] = 2, ["y"] = 1, ["z"] = 2, ["name"] = "default:furnace"},
  {["x"] = 2, ["y"] = 1, ["z"] = 5, ["name"] = "default:stone"},
  {["x"] = 3, ["y"] = 1, ["z"] = 4, ["name"] = "default:chest"},
  {["x"] = 3, ["y"] = 1, ["z"] = 5, ["name"] = "default:stone"},
  {["x"] = 4, ["y"] = 1, ["z"] = 0, ["name"] = "default:stone"},
  {["x"] = 4, ["y"] = 1, ["z"] = 2, ["name"] = "default:furnace"},
  {["x"] = 4, ["y"] = 1, ["z"] = 5, ["name"] = "default:stone"},
  {["x"] = 5, ["y"] = 1, ["z"] = 0, ["name"] = "default:stone"},
  {["x"] = 5, ["y"] = 1, ["z"] = 5, ["name"] = "default:stone"},
  {["x"] = 6, ["y"] = 1, ["z"] = 0, ["name"] = "default:stone"},
  {["x"] = 6, ["y"] = 1, ["z"] = 1, ["name"] = "default:stone"},
  {["x"] = 6, ["y"] = 1, ["z"] = 2, ["name"] = "default:stone"},
  {["x"] = 6, ["y"] = 1, ["z"] = 3, ["name"] = "default:stone"},
  {["x"] = 6, ["y"] = 1, ["z"] = 4, ["name"] = "default:stone"},
  {["x"] = 6, ["y"] = 1, ["z"] = 5, ["name"] = "default:stone"},
  {["x"] = 0, ["y"] = 2, ["z"] = 0, ["name"] = "default:stone"},
  {["x"] = 0, ["y"] = 2, ["z"] = 1, ["name"] = "default:stone"},
  {["x"] = 0, ["y"] = 2, ["z"] = 2, ["name"] = "default:stone"},
  {["x"] = 0, ["y"] = 2, ["z"] = 3, ["name"] = "default:stone"},
  {["x"] = 0, ["y"] = 2, ["z"] = 4, ["name"] = "default:stone"},
  {["x"] = 0, ["y"] = 2, ["z"] = 5, ["name"] = "default:stone"},
  {["x"] = 1, ["y"] = 2, ["z"] = 0, ["name"] = "default:stone"},
  {["x"] = 1, ["y"] = 2, ["z"] = 5, ["name"] = "default:stone"},
  {["x"] = 2, ["y"] = 2, ["z"] = 0, ["name"] = "default:stone"},
  {["x"] = 2, ["y"] = 2, ["z"] = 5, ["name"] = "default:stone"},
  {["x"] = 3, ["y"] = 2, ["z"] = 5, ["name"] = "default:stone"},
  {["x"] = 4, ["y"] = 2, ["z"] = 0, ["name"] = "default:stone"},
  {["x"] = 4, ["y"] = 2, ["z"] = 5, ["name"] = "default:stone"},
  {["x"] = 5, ["y"] = 2, ["z"] = 0, ["name"] = "default:stone"},
  {["x"] = 5, ["y"] = 2, ["z"] = 5, ["name"] = "default:stone"},
  {["x"] = 6, ["y"] = 2, ["z"] = 0, ["name"] = "default:stone"},
  {["x"] = 6, ["y"] = 2, ["z"] = 1, ["name"] = "default:stone"},
  {["x"] = 6, ["y"] = 2, ["z"] = 2, ["name"] = "default:stone"},
  {["x"] = 6, ["y"] = 2, ["z"] = 3, ["name"] = "default:stone"},
  {["x"] = 6, ["y"] = 2, ["z"] = 4, ["name"] = "default:stone"},
  {["x"] = 6, ["y"] = 2, ["z"] = 5, ["name"] = "default:stone"},
  {["x"] = 0, ["y"] = 3, ["z"] = 0, ["name"] = "default:stone"},
  {["x"] = 0, ["y"] = 3, ["z"] = 1, ["name"] = "default:stone"},
  {["x"] = 0, ["y"] = 3, ["z"] = 2, ["name"] = "default:stone"},
  {["x"] = 0, ["y"] = 3, ["z"] = 3, ["name"] = "default:stone"},
  {["x"] = 0, ["y"] = 3, ["z"] = 4, ["name"] = "default:stone"},
  {["x"] = 0, ["y"] = 3, ["z"] = 5, ["name"] = "default:stone"},
  {["x"] = 1, ["y"] = 3, ["z"] = 0, ["name"] = "default:stone"},
  {["x"] = 1, ["y"] = 3, ["z"] = 5, ["name"] = "default:stone"},
  {["x"] = 2, ["y"] = 3, ["z"] = 0, ["name"] = "default:stone"},
  {["x"] = 2, ["y"] = 3, ["z"] = 5, ["name"] = "default:stone"},
  {["x"] = 3, ["y"] = 3, ["z"] = 0, ["name"] = "default:stone"},
  {["x"] = 3, ["y"] = 3, ["z"] = 5, ["name"] = "default:stone"},
  {["x"] = 4, ["y"] = 3, ["z"] = 0, ["name"] = "default:stone"},
  {["x"] = 4, ["y"] = 3, ["z"] = 5, ["name"] = "default:stone"},
  {["x"] = 5, ["y"] = 3, ["z"] = 0, ["name"] = "default:stone"},
  {["x"] = 5, ["y"] = 3, ["z"] = 5, ["name"] = "default:stone"},
  {["x"] = 6, ["y"] = 3, ["z"] = 0, ["name"] = "default:stone"},
  {["x"] = 6, ["y"] = 3, ["z"] = 1, ["name"] = "default:stone"},
  {["x"] = 6, ["y"] = 3, ["z"] = 2, ["name"] = "default:stone"},
  {["x"] = 6, ["y"] = 3, ["z"] = 3, ["name"] = "default:stone"},
  {["x"] = 6, ["y"] = 3, ["z"] = 4, ["name"] = "default:stone"},
  {["x"] = 6, ["y"] = 3, ["z"] = 5, ["name"] = "default:stone"},
  {["x"] = 0, ["y"] = 4, ["z"] = 0, ["name"] = "default:stone"},
  {["x"] = 0, ["y"] = 4, ["z"] = 1, ["name"] = "default:stone"},
  {["x"] = 0, ["y"] = 4, ["z"] = 2, ["name"] = "default:stone"},
  {["x"] = 0, ["y"] = 4, ["z"] = 3, ["name"] = "default:stone"},
  {["x"] = 0, ["y"] = 4, ["z"] = 4, ["name"] = "default:stone"},
  {["x"] = 0, ["y"] = 4, ["z"] = 5, ["name"] = "default:stone"},
  {["x"] = 1, ["y"] = 4, ["z"] = 0, ["name"] = "default:stone"},
  {["x"] = 1, ["y"] = 4, ["z"] = 1, ["name"] = "default:stone"},
  {["x"] = 1, ["y"] = 4, ["z"] = 2, ["name"] = "default:stone"},
  {["x"] = 1, ["y"] = 4, ["z"] = 3, ["name"] = "default:stone"},
  {["x"] = 1, ["y"] = 4, ["z"] = 4, ["name"] = "default:stone"},
  {["x"] = 1, ["y"] = 4, ["z"] = 5, ["name"] = "default:stone"},
  {["x"] = 2, ["y"] = 4, ["z"] = 0, ["name"] = "default:stone"},
  {["x"] = 2, ["y"] = 4, ["z"] = 1, ["name"] = "default:stone"},
  {["x"] = 2, ["y"] = 4, ["z"] = 2, ["name"] = "default:stone"},
  {["x"] = 2, ["y"] = 4, ["z"] = 3, ["name"] = "default:stone"},
  {["x"] = 2, ["y"] = 4, ["z"] = 4, ["name"] = "default:stone"},
  {["x"] = 2, ["y"] = 4, ["z"] = 5, ["name"] = "default:stone"},
  {["x"] = 3, ["y"] = 4, ["z"] = 0, ["name"] = "default:stone"},
  {["x"] = 3, ["y"] = 4, ["z"] = 1, ["name"] = "default:stone"},
  {["x"] = 3, ["y"] = 4, ["z"] = 2, ["name"] = "default:stone"},
  {["x"] = 3, ["y"] = 4, ["z"] = 3, ["name"] = "default:stone"},
  {["x"] = 3, ["y"] = 4, ["z"] = 4, ["name"] = "default:stone"},
  {["x"] = 3, ["y"] = 4, ["z"] = 5, ["name"] = "default:stone"},
  {["x"] = 4, ["y"] = 4, ["z"] = 0, ["name"] = "default:stone"},
  {["x"] = 4, ["y"] = 4, ["z"] = 1, ["name"] = "default:stone"},
  {["x"] = 4, ["y"] = 4, ["z"] = 2, ["name"] = "default:stone"},
  {["x"] = 4, ["y"] = 4, ["z"] = 3, ["name"] = "default:stone"},
  {["x"] = 4, ["y"] = 4, ["z"] = 4, ["name"] = "default:stone"},
  {["x"] = 4, ["y"] = 4, ["z"] = 5, ["name"] = "default:stone"},
  {["x"] = 5, ["y"] = 4, ["z"] = 0, ["name"] = "default:stone"},
  {["x"] = 5, ["y"] = 4, ["z"] = 1, ["name"] = "default:stone"},
  {["x"] = 5, ["y"] = 4, ["z"] = 2, ["name"] = "default:stone"},
  {["x"] = 5, ["y"] = 4, ["z"] = 3, ["name"] = "default:stone"},
  {["x"] = 5, ["y"] = 4, ["z"] = 4, ["name"] = "default:stone"},
  {["x"] = 5, ["y"] = 4, ["z"] = 5, ["name"] = "default:stone"},
  {["x"] = 6, ["y"] = 4, ["z"] = 0, ["name"] = "default:stone"},
  {["x"] = 6, ["y"] = 4, ["z"] = 1, ["name"] = "default:stone"},
  {["x"] = 6, ["y"] = 4, ["z"] = 2, ["name"] = "default:stone"},
  {["x"] = 6, ["y"] = 4, ["z"] = 3, ["name"] = "default:stone"},
  {["x"] = 6, ["y"] = 4, ["z"] = 4, ["name"] = "default:stone"},
  {["x"] = 6, ["y"] = 4, ["z"] = 5, ["name"] = "default:stone"}
}
