return {
  {["x"] = 0, ["y"] = 0, ["z"] = 0, ["name"] = "default:cobble"},
  {["x"] = 0, ["y"] = 0, ["z"] = 1, ["name"] = "default:cobble"},
  {["x"] = 0, ["y"] = 0, ["z"] = 2, ["name"] = "default:cobble"},
  {["x"] = 0, ["y"] = 0, ["z"] = 3, ["name"] = "default:cobble"},
  {["x"] = 0, ["y"] = 0, ["z"] = 4, ["name"] = "default:cobble"},
  {["x"] = 0, ["y"] = 0, ["z"] = 5, ["name"] = "default:cobble"},
  {["x"] = 0, ["y"] = 0, ["z"] = 6, ["name"] = "default:cobble"},
  {["x"] = 0, ["y"] = 0, ["z"] = 7, ["name"] = "default:cobble"},
  {["x"] = 0, ["y"] = 0, ["z"] = 8, ["name"] = "default:cobble"},
  {["x"] = 0, ["y"] = 0, ["z"] = 9, ["name"] = "default:cobble"},
  {["x"] = 0, ["y"] = 0, ["z"] = 10, ["name"] = "default:cobble"},
  {["x"] = 0, ["y"] = 0, ["z"] = 11, ["name"] = "default:cobble"},
  {["x"] = 0, ["y"] = 0, ["z"] = 12, ["name"] = "default:cobble"},
  {["x"] = 1, ["y"] = 0, ["z"] = 0, ["name"] = "default:cobble"},
  {["x"] = 1, ["y"] = 0, ["z"] = 1, ["name"] = "default:cobble"},
  {["x"] = 1, ["y"] = 0, ["z"] = 2, ["name"] = "default:cobble"},
  {["x"] = 1, ["y"] = 0, ["z"] = 3, ["name"] = "default:cobble"},
  {["x"] = 1, ["y"] = 0, ["z"] = 4, ["name"] = "default:cobble"},
  {["x"] = 1, ["y"] = 0, ["z"] = 5, ["name"] = "default:cobble"},
  {["x"] = 1, ["y"] = 0, ["z"] = 6, ["name"] = "default:cobble"},
  {["x"] = 1, ["y"] = 0, ["z"] = 7, ["name"] = "default:cobble"},
  {["x"] = 1, ["y"] = 0, ["z"] = 8, ["name"] = "default:cobble"},
  {["x"] = 1, ["y"] = 0, ["z"] = 9, ["name"] = "default:cobble"},
  {["x"] = 1, ["y"] = 0, ["z"] = 10, ["name"] = "default:cobble"},
  {["x"] = 1, ["y"] = 0, ["z"] = 11, ["name"] = "default:cobble"},
  {["x"] = 1, ["y"] = 0, ["z"] = 12, ["name"] = "default:cobble"},
  {["x"] = 2, ["y"] = 0, ["z"] = 0, ["name"] = "default:cobble"},
  {["x"] = 2, ["y"] = 0, ["z"] = 1, ["name"] = "default:cobble"},
  {["x"] = 2, ["y"] = 0, ["z"] = 2, ["name"] = "default:cobble"},
  {["x"] = 2, ["y"] = 0, ["z"] = 3, ["name"] = "default:cobble"},
  {["x"] = 2, ["y"] = 0, ["z"] = 4, ["name"] = "default:cobble"},
  {["x"] = 2, ["y"] = 0, ["z"] = 5, ["name"] = "default:cobble"},
  {["x"] = 2, ["y"] = 0, ["z"] = 6, ["name"] = "default:cobble"},
  {["x"] = 2, ["y"] = 0, ["z"] = 7, ["name"] = "default:cobble"},
  {["x"] = 2, ["y"] = 0, ["z"] = 8, ["name"] = "default:cobble"},
  {["x"] = 2, ["y"] = 0, ["z"] = 9, ["name"] = "default:cobble"},
  {["x"] = 2, ["y"] = 0, ["z"] = 10, ["name"] = "default:cobble"},
  {["x"] = 2, ["y"] = 0, ["z"] = 11, ["name"] = "default:cobble"},
  {["x"] = 2, ["y"] = 0, ["z"] = 12, ["name"] = "default:cobble"},
  {["x"] = 3, ["y"] = 0, ["z"] = 0, ["name"] = "default:cobble"},
  {["x"] = 3, ["y"] = 0, ["z"] = 1, ["name"] = "default:cobble"},
  {["x"] = 3, ["y"] = 0, ["z"] = 2, ["name"] = "default:cobble"},
  {["x"] = 3, ["y"] = 0, ["z"] = 3, ["name"] = "default:cobble"},
  {["x"] = 3, ["y"] = 0, ["z"] = 4, ["name"] = "default:cobble"},
  {["x"] = 3, ["y"] = 0, ["z"] = 5, ["name"] = "default:cobble"},
  {["x"] = 3, ["y"] = 0, ["z"] = 6, ["name"] = "default:cobble"},
  {["x"] = 3, ["y"] = 0, ["z"] = 7, ["name"] = "default:cobble"},
  {["x"] = 3, ["y"] = 0, ["z"] = 8, ["name"] = "default:cobble"},
  {["x"] = 3, ["y"] = 0, ["z"] = 9, ["name"] = "default:cobble"},
  {["x"] = 3, ["y"] = 0, ["z"] = 10, ["name"] = "default:cobble"},
  {["x"] = 3, ["y"] = 0, ["z"] = 11, ["name"] = "default:cobble"},
  {["x"] = 3, ["y"] = 0, ["z"] = 12, ["name"] = "default:cobble"},
  {["x"] = 4, ["y"] = 0, ["z"] = 0, ["name"] = "default:cobble"},
  {["x"] = 4, ["y"] = 0, ["z"] = 1, ["name"] = "default:cobble"},
  {["x"] = 4, ["y"] = 0, ["z"] = 2, ["name"] = "default:cobble"},
  {["x"] = 4, ["y"] = 0, ["z"] = 3, ["name"] = "default:cobble"},
  {["x"] = 4, ["y"] = 0, ["z"] = 4, ["name"] = "default:cobble"},
  {["x"] = 4, ["y"] = 0, ["z"] = 5, ["name"] = "default:cobble"},
  {["x"] = 4, ["y"] = 0, ["z"] = 6, ["name"] = "default:cobble"},
  {["x"] = 4, ["y"] = 0, ["z"] = 7, ["name"] = "default:cobble"},
  {["x"] = 4, ["y"] = 0, ["z"] = 8, ["name"] = "default:cobble"},
  {["x"] = 4, ["y"] = 0, ["z"] = 9, ["name"] = "default:cobble"},
  {["x"] = 4, ["y"] = 0, ["z"] = 10, ["name"] = "default:cobble"},
  {["x"] = 4, ["y"] = 0, ["z"] = 11, ["name"] = "default:cobble"},
  {["x"] = 4, ["y"] = 0, ["z"] = 12, ["name"] = "default:cobble"},
  {["x"] = 5, ["y"] = 0, ["z"] = 0, ["name"] = "default:cobble"},
  {["x"] = 5, ["y"] = 0, ["z"] = 1, ["name"] = "default:cobble"},
  {["x"] = 5, ["y"] = 0, ["z"] = 2, ["name"] = "default:cobble"},
  {["x"] = 5, ["y"] = 0, ["z"] = 3, ["name"] = "default:cobble"},
  {["x"] = 5, ["y"] = 0, ["z"] = 4, ["name"] = "default:cobble"},
  {["x"] = 5, ["y"] = 0, ["z"] = 5, ["name"] = "default:cobble"},
  {["x"] = 5, ["y"] = 0, ["z"] = 6, ["name"] = "default:cobble"},
  {["x"] = 5, ["y"] = 0, ["z"] = 7, ["name"] = "default:cobble"},
  {["x"] = 5, ["y"] = 0, ["z"] = 8, ["name"] = "default:cobble"},
  {["x"] = 5, ["y"] = 0, ["z"] = 9, ["name"] = "default:cobble"},
  {["x"] = 5, ["y"] = 0, ["z"] = 10, ["name"] = "default:cobble"},
  {["x"] = 5, ["y"] = 0, ["z"] = 11, ["name"] = "default:cobble"},
  {["x"] = 5, ["y"] = 0, ["z"] = 12, ["name"] = "default:cobble"},
  {["x"] = 6, ["y"] = 0, ["z"] = 0, ["name"] = "default:cobble"},
  {["x"] = 6, ["y"] = 0, ["z"] = 1, ["name"] = "default:cobble"},
  {["x"] = 6, ["y"] = 0, ["z"] = 2, ["name"] = "default:cobble"},
  {["x"] = 6, ["y"] = 0, ["z"] = 3, ["name"] = "default:cobble"},
  {["x"] = 6, ["y"] = 0, ["z"] = 4, ["name"] = "default:cobble"},
  {["x"] = 6, ["y"] = 0, ["z"] = 5, ["name"] = "default:cobble"},
  {["x"] = 6, ["y"] = 0, ["z"] = 6, ["name"] = "default:cobble"},
  {["x"] = 6, ["y"] = 0, ["z"] = 7, ["name"] = "default:cobble"},
  {["x"] = 6, ["y"] = 0, ["z"] = 8, ["name"] = "default:cobble"},
  {["x"] = 6, ["y"] = 0, ["z"] = 9, ["name"] = "default:cobble"},
  {["x"] = 6, ["y"] = 0, ["z"] = 10, ["name"] = "default:cobble"},
  {["x"] = 6, ["y"] = 0, ["z"] = 11, ["name"] = "default:cobble"},
  {["x"] = 6, ["y"] = 0, ["z"] = 12, ["name"] = "default:cobble"},
  {["x"] = 7, ["y"] = 0, ["z"] = 0, ["name"] = "default:cobble"},
  {["x"] = 7, ["y"] = 0, ["z"] = 1, ["name"] = "default:cobble"},
  {["x"] = 7, ["y"] = 0, ["z"] = 2, ["name"] = "default:cobble"},
  {["x"] = 7, ["y"] = 0, ["z"] = 3, ["name"] = "default:cobble"},
  {["x"] = 7, ["y"] = 0, ["z"] = 4, ["name"] = "default:cobble"},
  {["x"] = 7, ["y"] = 0, ["z"] = 5, ["name"] = "default:cobble"},
  {["x"] = 7, ["y"] = 0, ["z"] = 6, ["name"] = "default:cobble"},
  {["x"] = 7, ["y"] = 0, ["z"] = 7, ["name"] = "default:cobble"},
  {["x"] = 7, ["y"] = 0, ["z"] = 8, ["name"] = "default:cobble"},
  {["x"] = 7, ["y"] = 0, ["z"] = 9, ["name"] = "default:cobble"},
  {["x"] = 7, ["y"] = 0, ["z"] = 10, ["name"] = "default:cobble"},
  {["x"] = 7, ["y"] = 0, ["z"] = 11, ["name"] = "default:cobble"},
  {["x"] = 7, ["y"] = 0, ["z"] = 12, ["name"] = "default:cobble"},
  {["x"] = 8, ["y"] = 0, ["z"] = 0, ["name"] = "default:cobble"},
  {["x"] = 8, ["y"] = 0, ["z"] = 1, ["name"] = "default:cobble"},
  {["x"] = 8, ["y"] = 0, ["z"] = 2, ["name"] = "default:cobble"},
  {["x"] = 8, ["y"] = 0, ["z"] = 3, ["name"] = "default:cobble"},
  {["x"] = 8, ["y"] = 0, ["z"] = 4, ["name"] = "default:cobble"},
  {["x"] = 8, ["y"] = 0, ["z"] = 5, ["name"] = "default:cobble"},
  {["x"] = 8, ["y"] = 0, ["z"] = 6, ["name"] = "default:cobble"},
  {["x"] = 8, ["y"] = 0, ["z"] = 7, ["name"] = "default:cobble"},
  {["x"] = 8, ["y"] = 0, ["z"] = 8, ["name"] = "default:cobble"},
  {["x"] = 8, ["y"] = 0, ["z"] = 9, ["name"] = "default:cobble"},
  {["x"] = 8, ["y"] = 0, ["z"] = 10, ["name"] = "default:cobble"},
  {["x"] = 8, ["y"] = 0, ["z"] = 11, ["name"] = "default:cobble"},
  {["x"] = 8, ["y"] = 0, ["z"] = 12, ["name"] = "default:cobble"},
  {["x"] = 9, ["y"] = 0, ["z"] = 0, ["name"] = "default:cobble"},
  {["x"] = 9, ["y"] = 0, ["z"] = 1, ["name"] = "default:cobble"},
  {["x"] = 9, ["y"] = 0, ["z"] = 2, ["name"] = "default:cobble"},
  {["x"] = 9, ["y"] = 0, ["z"] = 3, ["name"] = "default:cobble"},
  {["x"] = 9, ["y"] = 0, ["z"] = 4, ["name"] = "default:cobble"},
  {["x"] = 9, ["y"] = 0, ["z"] = 5, ["name"] = "default:cobble"},
  {["x"] = 9, ["y"] = 0, ["z"] = 6, ["name"] = "default:cobble"},
  {["x"] = 9, ["y"] = 0, ["z"] = 7, ["name"] = "default:cobble"},
  {["x"] = 9, ["y"] = 0, ["z"] = 8, ["name"] = "default:cobble"},
  {["x"] = 9, ["y"] = 0, ["z"] = 9, ["name"] = "default:cobble"},
  {["x"] = 9, ["y"] = 0, ["z"] = 10, ["name"] = "default:cobble"},
  {["x"] = 9, ["y"] = 0, ["z"] = 11, ["name"] = "default:cobble"},
  {["x"] = 9, ["y"] = 0, ["z"] = 12, ["name"] = "default:cobble"},
  {["x"] = 10, ["y"] = 0, ["z"] = 0, ["name"] = "default:cobble"},
  {["x"] = 10, ["y"] = 0, ["z"] = 1, ["name"] = "default:cobble"},
  {["x"] = 10, ["y"] = 0, ["z"] = 2, ["name"] = "default:cobble"},
  {["x"] = 10, ["y"] = 0, ["z"] = 3, ["name"] = "default:cobble"},
  {["x"] = 10, ["y"] = 0, ["z"] = 4, ["name"] = "default:cobble"},
  {["x"] = 10, ["y"] = 0, ["z"] = 5, ["name"] = "default:cobble"},
  {["x"] = 10, ["y"] = 0, ["z"] = 6, ["name"] = "default:cobble"},
  {["x"] = 10, ["y"] = 0, ["z"] = 7, ["name"] = "default:cobble"},
  {["x"] = 10, ["y"] = 0, ["z"] = 8, ["name"] = "default:cobble"},
  {["x"] = 10, ["y"] = 0, ["z"] = 9, ["name"] = "default:cobble"},
  {["x"] = 10, ["y"] = 0, ["z"] = 10, ["name"] = "default:cobble"},
  {["x"] = 10, ["y"] = 0, ["z"] = 11, ["name"] = "default:cobble"},
  {["x"] = 10, ["y"] = 0, ["z"] = 12, ["name"] = "default:cobble"},
  {["x"] = 11, ["y"] = 0, ["z"] = 0, ["name"] = "default:cobble"},
  {["x"] = 11, ["y"] = 0, ["z"] = 1, ["name"] = "default:cobble"},
  {["x"] = 11, ["y"] = 0, ["z"] = 2, ["name"] = "default:cobble"},
  {["x"] = 11, ["y"] = 0, ["z"] = 3, ["name"] = "default:cobble"},
  {["x"] = 11, ["y"] = 0, ["z"] = 4, ["name"] = "default:cobble"},
  {["x"] = 11, ["y"] = 0, ["z"] = 5, ["name"] = "default:cobble"},
  {["x"] = 11, ["y"] = 0, ["z"] = 6, ["name"] = "default:cobble"},
  {["x"] = 11, ["y"] = 0, ["z"] = 7, ["name"] = "default:cobble"},
  {["x"] = 11, ["y"] = 0, ["z"] = 8, ["name"] = "default:cobble"},
  {["x"] = 11, ["y"] = 0, ["z"] = 9, ["name"] = "default:cobble"},
  {["x"] = 11, ["y"] = 0, ["z"] = 10, ["name"] = "default:cobble"},
  {["x"] = 11, ["y"] = 0, ["z"] = 11, ["name"] = "default:cobble"},
  {["x"] = 11, ["y"] = 0, ["z"] = 12, ["name"] = "default:cobble"},
  {["x"] = 12, ["y"] = 0, ["z"] = 0, ["name"] = "default:cobble"},
  {["x"] = 12, ["y"] = 0, ["z"] = 1, ["name"] = "default:cobble"},
  {["x"] = 12, ["y"] = 0, ["z"] = 2, ["name"] = "default:cobble"},
  {["x"] = 12, ["y"] = 0, ["z"] = 3, ["name"] = "default:cobble"},
  {["x"] = 12, ["y"] = 0, ["z"] = 4, ["name"] = "default:cobble"},
  {["x"] = 12, ["y"] = 0, ["z"] = 5, ["name"] = "default:cobble"},
  {["x"] = 12, ["y"] = 0, ["z"] = 6, ["name"] = "default:cobble"},
  {["x"] = 12, ["y"] = 0, ["z"] = 7, ["name"] = "default:cobble"},
  {["x"] = 12, ["y"] = 0, ["z"] = 8, ["name"] = "default:cobble"},
  {["x"] = 12, ["y"] = 0, ["z"] = 9, ["name"] = "default:cobble"},
  {["x"] = 12, ["y"] = 0, ["z"] = 10, ["name"] = "default:cobble"},
  {["x"] = 12, ["y"] = 0, ["z"] = 11, ["name"] = "default:cobble"},
  {["x"] = 12, ["y"] = 0, ["z"] = 12, ["name"] = "default:cobble"},
  {["x"] = 0, ["y"] = 1, ["z"] = 0, ["name"] = "default:stone"},
  {["x"] = 0, ["y"] = 1, ["z"] = 1, ["name"] = "default:stone"},
  {["x"] = 0, ["y"] = 1, ["z"] = 2, ["name"] = "default:stone"},
  {["x"] = 0, ["y"] = 1, ["z"] = 3, ["name"] = "default:stone"},
  {["x"] = 0, ["y"] = 1, ["z"] = 4, ["name"] = "default:stone"},
  {["x"] = 0, ["y"] = 1, ["z"] = 5, ["name"] = "default:stone"},
  {["x"] = 0, ["y"] = 1, ["z"] = 6, ["name"] = "default:stone"},
  {["x"] = 0, ["y"] = 1, ["z"] = 7, ["name"] = "default:stone"},
  {["x"] = 0, ["y"] = 1, ["z"] = 8, ["name"] = "default:stone"},
  {["x"] = 0, ["y"] = 1, ["z"] = 9, ["name"] = "default:stone"},
  {["x"] = 0, ["y"] = 1, ["z"] = 10, ["name"] = "default:stone"},
  {["x"] = 0, ["y"] = 1, ["z"] = 11, ["name"] = "default:stone"},
  {["x"] = 0, ["y"] = 1, ["z"] = 12, ["name"] = "default:stone"},
  {["x"] = 1, ["y"] = 1, ["z"] = 0, ["name"] = "default:stone"},
  {["x"] = 1, ["y"] = 1, ["z"] = 1, ["name"] = "default:stone"},
  {["x"] = 1, ["y"] = 1, ["z"] = 6, ["name"] = "default:ladder_wood"},
  {["x"] = 1, ["y"] = 1, ["z"] = 11, ["name"] = "default:stone"},
  {["x"] = 1, ["y"] = 1, ["z"] = 12, ["name"] = "default:stone"},
  {["x"] = 2, ["y"] = 1, ["z"] = 0, ["name"] = "default:stone"},
  {["x"] = 2, ["y"] = 1, ["z"] = 2, ["name"] = "default:wood"},
  {["x"] = 2, ["y"] = 1, ["z"] = 12, ["name"] = "default:stone"},
  {["x"] = 3, ["y"] = 1, ["z"] = 0, ["name"] = "default:stone"},
  {["x"] = 3, ["y"] = 1, ["z"] = 12, ["name"] = "default:stone"},
  {["x"] = 4, ["y"] = 1, ["z"] = 0, ["name"] = "default:stone"},
  {["x"] = 4, ["y"] = 1, ["z"] = 12, ["name"] = "default:stone"},
  {["x"] = 5, ["y"] = 1, ["z"] = 12, ["name"] = "default:stone"},
  {["x"] = 6, ["y"] = 1, ["z"] = 12, ["name"] = "default:stone"},
  {["x"] = 7, ["y"] = 1, ["z"] = 0, ["name"] = "default:stone"},
  {["x"] = 7, ["y"] = 1, ["z"] = 12, ["name"] = "default:stone"},
  {["x"] = 8, ["y"] = 1, ["z"] = 0, ["name"] = "default:stone"},
  {["x"] = 8, ["y"] = 1, ["z"] = 12, ["name"] = "default:stone"},
  {["x"] = 9, ["y"] = 1, ["z"] = 0, ["name"] = "default:stone"},
  {["x"] = 9, ["y"] = 1, ["z"] = 12, ["name"] = "default:stone"},
  {["x"] = 10, ["y"] = 1, ["z"] = 0, ["name"] = "default:stone"},
  {["x"] = 10, ["y"] = 1, ["z"] = 12, ["name"] = "default:stone"},
  {["x"] = 11, ["y"] = 1, ["z"] = 0, ["name"] = "default:stone"},
  {["x"] = 11, ["y"] = 1, ["z"] = 1, ["name"] = "default:stone"},
  {["x"] = 11, ["y"] = 1, ["z"] = 11, ["name"] = "default:stone"},
  {["x"] = 11, ["y"] = 1, ["z"] = 12, ["name"] = "default:stone"},
  {["x"] = 12, ["y"] = 1, ["z"] = 0, ["name"] = "default:stone"},
  {["x"] = 12, ["y"] = 1, ["z"] = 1, ["name"] = "default:stone"},
  {["x"] = 12, ["y"] = 1, ["z"] = 2, ["name"] = "default:stone"},
  {["x"] = 12, ["y"] = 1, ["z"] = 3, ["name"] = "default:stone"},
  {["x"] = 12, ["y"] = 1, ["z"] = 4, ["name"] = "default:stone"},
  {["x"] = 12, ["y"] = 1, ["z"] = 5, ["name"] = "default:stone"},
  {["x"] = 12, ["y"] = 1, ["z"] = 6, ["name"] = "default:stone"},
  {["x"] = 12, ["y"] = 1, ["z"] = 7, ["name"] = "default:stone"},
  {["x"] = 12, ["y"] = 1, ["z"] = 8, ["name"] = "default:stone"},
  {["x"] = 12, ["y"] = 1, ["z"] = 9, ["name"] = "default:stone"},
  {["x"] = 12, ["y"] = 1, ["z"] = 10, ["name"] = "default:stone"},
  {["x"] = 12, ["y"] = 1, ["z"] = 11, ["name"] = "default:stone"},
  {["x"] = 12, ["y"] = 1, ["z"] = 12, ["name"] = "default:stone"},
  {["x"] = 0, ["y"] = 2, ["z"] = 0, ["name"] = "default:stone"},
  {["x"] = 0, ["y"] = 2, ["z"] = 1, ["name"] = "default:stone"},
  {["x"] = 0, ["y"] = 2, ["z"] = 2, ["name"] = "default:stone"},
  {["x"] = 0, ["y"] = 2, ["z"] = 3, ["name"] = "default:stone"},
  {["x"] = 0, ["y"] = 2, ["z"] = 4, ["name"] = "default:stone"},
  {["x"] = 0, ["y"] = 2, ["z"] = 5, ["name"] = "default:stone"},
  {["x"] = 0, ["y"] = 2, ["z"] = 6, ["name"] = "default:stone"},
  {["x"] = 0, ["y"] = 2, ["z"] = 7, ["name"] = "default:stone"},
  {["x"] = 0, ["y"] = 2, ["z"] = 8, ["name"] = "default:stone"},
  {["x"] = 0, ["y"] = 2, ["z"] = 9, ["name"] = "default:stone"},
  {["x"] = 0, ["y"] = 2, ["z"] = 10, ["name"] = "default:stone"},
  {["x"] = 0, ["y"] = 2, ["z"] = 11, ["name"] = "default:stone"},
  {["x"] = 0, ["y"] = 2, ["z"] = 12, ["name"] = "default:stone"},
  {["x"] = 1, ["y"] = 2, ["z"] = 0, ["name"] = "default:stone"},
  {["x"] = 1, ["y"] = 2, ["z"] = 1, ["name"] = "default:stone"},
  {["x"] = 1, ["y"] = 2, ["z"] = 6, ["name"] = "default:ladder_wood"},
  {["x"] = 1, ["y"] = 2, ["z"] = 11, ["name"] = "default:stone"},
  {["x"] = 1, ["y"] = 2, ["z"] = 12, ["name"] = "default:stone"},
  {["x"] = 2, ["y"] = 2, ["z"] = 0, ["name"] = "default:stone"},
  {["x"] = 2, ["y"] = 2, ["z"] = 12, ["name"] = "default:stone"},
  {["x"] = 3, ["y"] = 2, ["z"] = 0, ["name"] = "default:stone"},
  {["x"] = 3, ["y"] = 2, ["z"] = 2, ["name"] = "default:wood"},
  {["x"] = 3, ["y"] = 2, ["z"] = 12, ["name"] = "default:stone"},
  {["x"] = 4, ["y"] = 2, ["z"] = 0, ["name"] = "default:stone"},
  {["x"] = 4, ["y"] = 2, ["z"] = 12, ["name"] = "default:stone"},
  {["x"] = 5, ["y"] = 2, ["z"] = 12, ["name"] = "default:stone"},
  {["x"] = 6, ["y"] = 2, ["z"] = 12, ["name"] = "default:stone"},
  {["x"] = 7, ["y"] = 2, ["z"] = 0, ["name"] = "default:stone"},
  {["x"] = 7, ["y"] = 2, ["z"] = 12, ["name"] = "default:stone"},
  {["x"] = 8, ["y"] = 2, ["z"] = 0, ["name"] = "default:stone"},
  {["x"] = 8, ["y"] = 2, ["z"] = 12, ["name"] = "default:stone"},
  {["x"] = 9, ["y"] = 2, ["z"] = 0, ["name"] = "default:stone"},
  {["x"] = 9, ["y"] = 2, ["z"] = 12, ["name"] = "default:stone"},
  {["x"] = 10, ["y"] = 2, ["z"] = 0, ["name"] = "default:stone"},
  {["x"] = 10, ["y"] = 2, ["z"] = 12, ["name"] = "default:stone"},
  {["x"] = 11, ["y"] = 2, ["z"] = 0, ["name"] = "default:stone"},
  {["x"] = 11, ["y"] = 2, ["z"] = 1, ["name"] = "default:stone"},
  {["x"] = 11, ["y"] = 2, ["z"] = 11, ["name"] = "default:stone"},
  {["x"] = 11, ["y"] = 2, ["z"] = 12, ["name"] = "default:stone"},
  {["x"] = 12, ["y"] = 2, ["z"] = 0, ["name"] = "default:stone"},
  {["x"] = 12, ["y"] = 2, ["z"] = 1, ["name"] = "default:stone"},
  {["x"] = 12, ["y"] = 2, ["z"] = 2, ["name"] = "default:stone"},
  {["x"] = 12, ["y"] = 2, ["z"] = 3, ["name"] = "default:stone"},
  {["x"] = 12, ["y"] = 2, ["z"] = 4, ["name"] = "default:stone"},
  {["x"] = 12, ["y"] = 2, ["z"] = 5, ["name"] = "default:stone"},
  {["x"] = 12, ["y"] = 2, ["z"] = 6, ["name"] = "default:stone"},
  {["x"] = 12, ["y"] = 2, ["z"] = 7, ["name"] = "default:stone"},
  {["x"] = 12, ["y"] = 2, ["z"] = 8, ["name"] = "default:stone"},
  {["x"] = 12, ["y"] = 2, ["z"] = 9, ["name"] = "default:stone"},
  {["x"] = 12, ["y"] = 2, ["z"] = 10, ["name"] = "default:stone"},
  {["x"] = 12, ["y"] = 2, ["z"] = 11, ["name"] = "default:stone"},
  {["x"] = 12, ["y"] = 2, ["z"] = 12, ["name"] = "default:stone"},
  {["x"] = 0, ["y"] = 3, ["z"] = 0, ["name"] = "default:stone"},
  {["x"] = 0, ["y"] = 3, ["z"] = 1, ["name"] = "default:stone"},
  {["x"] = 0, ["y"] = 3, ["z"] = 2, ["name"] = "default:stone"},
  {["x"] = 0, ["y"] = 3, ["z"] = 4, ["name"] = "default:stone"},
  {["x"] = 0, ["y"] = 3, ["z"] = 5, ["name"] = "default:stone"},
  {["x"] = 0, ["y"] = 3, ["z"] = 7, ["name"] = "default:stone"},
  {["x"] = 0, ["y"] = 3, ["z"] = 8, ["name"] = "default:stone"},
  {["x"] = 0, ["y"] = 3, ["z"] = 10, ["name"] = "default:stone"},
  {["x"] = 0, ["y"] = 3, ["z"] = 11, ["name"] = "default:stone"},
  {["x"] = 0, ["y"] = 3, ["z"] = 12, ["name"] = "default:stone"},
  {["x"] = 1, ["y"] = 3, ["z"] = 0, ["name"] = "default:stone"},
  {["x"] = 1, ["y"] = 3, ["z"] = 1, ["name"] = "default:stone"},
  {["x"] = 1, ["y"] = 3, ["z"] = 6, ["name"] = "default:ladder_wood"},
  {["x"] = 1, ["y"] = 3, ["z"] = 11, ["name"] = "default:stone"},
  {["x"] = 1, ["y"] = 3, ["z"] = 12, ["name"] = "default:stone"},
  {["x"] = 2, ["y"] = 3, ["z"] = 0, ["name"] = "default:stone"},
  {["x"] = 2, ["y"] = 3, ["z"] = 12, ["name"] = "default:stone"},
  {["x"] = 4, ["y"] = 3, ["z"] = 0, ["name"] = "default:stone"},
  {["x"] = 4, ["y"] = 3, ["z"] = 2, ["name"] = "default:wood"},
  {["x"] = 4, ["y"] = 3, ["z"] = 12, ["name"] = "default:stone"},
  {["x"] = 5, ["y"] = 3, ["z"] = 0, ["name"] = "default:stone"},
  {["x"] = 5, ["y"] = 3, ["z"] = 12, ["name"] = "default:stone"},
  {["x"] = 6, ["y"] = 3, ["z"] = 0, ["name"] = "default:stone"},
  {["x"] = 7, ["y"] = 3, ["z"] = 0, ["name"] = "default:stone"},
  {["x"] = 7, ["y"] = 3, ["z"] = 12, ["name"] = "default:stone"},
  {["x"] = 8, ["y"] = 3, ["z"] = 0, ["name"] = "default:stone"},
  {["x"] = 8, ["y"] = 3, ["z"] = 12, ["name"] = "default:stone"},
  {["x"] = 10, ["y"] = 3, ["z"] = 0, ["name"] = "default:stone"},
  {["x"] = 10, ["y"] = 3, ["z"] = 12, ["name"] = "default:stone"},
  {["x"] = 11, ["y"] = 3, ["z"] = 0, ["name"] = "default:stone"},
  {["x"] = 11, ["y"] = 3, ["z"] = 1, ["name"] = "default:stone"},
  {["x"] = 11, ["y"] = 3, ["z"] = 11, ["name"] = "default:stone"},
  {["x"] = 11, ["y"] = 3, ["z"] = 12, ["name"] = "default:stone"},
  {["x"] = 12, ["y"] = 3, ["z"] = 0, ["name"] = "default:stone"},
  {["x"] = 12, ["y"] = 3, ["z"] = 1, ["name"] = "default:stone"},
  {["x"] = 12, ["y"] = 3, ["z"] = 2, ["name"] = "default:stone"},
  {["x"] = 12, ["y"] = 3, ["z"] = 4, ["name"] = "default:stone"},
  {["x"] = 12, ["y"] = 3, ["z"] = 5, ["name"] = "default:stone"},
  {["x"] = 12, ["y"] = 3, ["z"] = 7, ["name"] = "default:stone"},
  {["x"] = 12, ["y"] = 3, ["z"] = 8, ["name"] = "default:stone"},
  {["x"] = 12, ["y"] = 3, ["z"] = 10, ["name"] = "default:stone"},
  {["x"] = 12, ["y"] = 3, ["z"] = 11, ["name"] = "default:stone"},
  {["x"] = 12, ["y"] = 3, ["z"] = 12, ["name"] = "default:stone"},
  {["x"] = 0, ["y"] = 4, ["z"] = 0, ["name"] = "default:stone"},
  {["x"] = 0, ["y"] = 4, ["z"] = 1, ["name"] = "default:stone"},
  {["x"] = 0, ["y"] = 4, ["z"] = 2, ["name"] = "default:stone"},
  {["x"] = 0, ["y"] = 4, ["z"] = 3, ["name"] = "default:stone"},
  {["x"] = 0, ["y"] = 4, ["z"] = 4, ["name"] = "default:stone"},
  {["x"] = 0, ["y"] = 4, ["z"] = 5, ["name"] = "default:stone"},
  {["x"] = 0, ["y"] = 4, ["z"] = 6, ["name"] = "default:stone"},
  {["x"] = 0, ["y"] = 4, ["z"] = 7, ["name"] = "default:stone"},
  {["x"] = 0, ["y"] = 4, ["z"] = 8, ["name"] = "default:stone"},
  {["x"] = 0, ["y"] = 4, ["z"] = 9, ["name"] = "default:stone"},
  {["x"] = 0, ["y"] = 4, ["z"] = 10, ["name"] = "default:stone"},
  {["x"] = 0, ["y"] = 4, ["z"] = 11, ["name"] = "default:stone"},
  {["x"] = 0, ["y"] = 4, ["z"] = 12, ["name"] = "default:stone"},
  {["x"] = 1, ["y"] = 4, ["z"] = 0, ["name"] = "default:stone"},
  {["x"] = 1, ["y"] = 4, ["z"] = 1, ["name"] = "default:stone"},
  {["x"] = 1, ["y"] = 4, ["z"] = 6, ["name"] = "default:ladder_wood"},
  {["x"] = 1, ["y"] = 4, ["z"] = 11, ["name"] = "default:stone"},
  {["x"] = 1, ["y"] = 4, ["z"] = 12, ["name"] = "default:stone"},
  {["x"] = 2, ["y"] = 4, ["z"] = 0, ["name"] = "default:stone"},
  {["x"] = 2, ["y"] = 4, ["z"] = 12, ["name"] = "default:stone"},
  {["x"] = 3, ["y"] = 4, ["z"] = 0, ["name"] = "default:stone"},
  {["x"] = 3, ["y"] = 4, ["z"] = 12, ["name"] = "default:stone"},
  {["x"] = 4, ["y"] = 4, ["z"] = 0, ["name"] = "default:stone"},
  {["x"] = 4, ["y"] = 4, ["z"] = 12, ["name"] = "default:stone"},
  {["x"] = 5, ["y"] = 4, ["z"] = 0, ["name"] = "default:stone"},
  {["x"] = 5, ["y"] = 4, ["z"] = 2, ["name"] = "default:wood"},
  {["x"] = 5, ["y"] = 4, ["z"] = 12, ["name"] = "default:stone"},
  {["x"] = 6, ["y"] = 4, ["z"] = 0, ["name"] = "default:stone"},
  {["x"] = 6, ["y"] = 4, ["z"] = 12, ["name"] = "default:stone"},
  {["x"] = 7, ["y"] = 4, ["z"] = 0, ["name"] = "default:stone"},
  {["x"] = 7, ["y"] = 4, ["z"] = 12, ["name"] = "default:stone"},
  {["x"] = 8, ["y"] = 4, ["z"] = 0, ["name"] = "default:stone"},
  {["x"] = 8, ["y"] = 4, ["z"] = 12, ["name"] = "default:stone"},
  {["x"] = 9, ["y"] = 4, ["z"] = 0, ["name"] = "default:stone"},
  {["x"] = 9, ["y"] = 4, ["z"] = 12, ["name"] = "default:stone"},
  {["x"] = 10, ["y"] = 4, ["z"] = 0, ["name"] = "default:stone"},
  {["x"] = 10, ["y"] = 4, ["z"] = 12, ["name"] = "default:stone"},
  {["x"] = 11, ["y"] = 4, ["z"] = 0, ["name"] = "default:stone"},
  {["x"] = 11, ["y"] = 4, ["z"] = 1, ["name"] = "default:stone"},
  {["x"] = 11, ["y"] = 4, ["z"] = 11, ["name"] = "default:stone"},
  {["x"] = 11, ["y"] = 4, ["z"] = 12, ["name"] = "default:stone"},
  {["x"] = 12, ["y"] = 4, ["z"] = 0, ["name"] = "default:stone"},
  {["x"] = 12, ["y"] = 4, ["z"] = 1, ["name"] = "default:stone"},
  {["x"] = 12, ["y"] = 4, ["z"] = 2, ["name"] = "default:stone"},
  {["x"] = 12, ["y"] = 4, ["z"] = 3, ["name"] = "default:stone"},
  {["x"] = 12, ["y"] = 4, ["z"] = 4, ["name"] = "default:stone"},
  {["x"] = 12, ["y"] = 4, ["z"] = 5, ["name"] = "default:stone"},
  {["x"] = 12, ["y"] = 4, ["z"] = 6, ["name"] = "default:stone"},
  {["x"] = 12, ["y"] = 4, ["z"] = 7, ["name"] = "default:stone"},
  {["x"] = 12, ["y"] = 4, ["z"] = 8, ["name"] = "default:stone"},
  {["x"] = 12, ["y"] = 4, ["z"] = 9, ["name"] = "default:stone"},
  {["x"] = 12, ["y"] = 4, ["z"] = 10, ["name"] = "default:stone"},
  {["x"] = 12, ["y"] = 4, ["z"] = 11, ["name"] = "default:stone"},
  {["x"] = 12, ["y"] = 4, ["z"] = 12, ["name"] = "default:stone"},
  {["x"] = 0, ["y"] = 5, ["z"] = 0, ["name"] = "default:stone"},
  {["x"] = 0, ["y"] = 5, ["z"] = 1, ["name"] = "default:stone"},
  {["x"] = 0, ["y"] = 5, ["z"] = 2, ["name"] = "default:stone"},
  {["x"] = 0, ["y"] = 5, ["z"] = 3, ["name"] = "default:stone"},
  {["x"] = 0, ["y"] = 5, ["z"] = 4, ["name"] = "default:stone"},
  {["x"] = 0, ["y"] = 5, ["z"] = 5, ["name"] = "default:stone"},
  {["x"] = 0, ["y"] = 5, ["z"] = 6, ["name"] = "default:stone"},
  {["x"] = 0, ["y"] = 5, ["z"] = 7, ["name"] = "default:stone"},
  {["x"] = 0, ["y"] = 5, ["z"] = 8, ["name"] = "default:stone"},
  {["x"] = 0, ["y"] = 5, ["z"] = 9, ["name"] = "default:stone"},
  {["x"] = 0, ["y"] = 5, ["z"] = 10, ["name"] = "default:stone"},
  {["x"] = 0, ["y"] = 5, ["z"] = 11, ["name"] = "default:stone"},
  {["x"] = 0, ["y"] = 5, ["z"] = 12, ["name"] = "default:stone"},
  {["x"] = 1, ["y"] = 5, ["z"] = 0, ["name"] = "default:stone"},
  {["x"] = 1, ["y"] = 5, ["z"] = 1, ["name"] = "default:stone"},
  {["x"] = 1, ["y"] = 5, ["z"] = 6, ["name"] = "default:ladder_wood"},
  {["x"] = 1, ["y"] = 5, ["z"] = 11, ["name"] = "default:stone"},
  {["x"] = 1, ["y"] = 5, ["z"] = 12, ["name"] = "default:stone"},
  {["x"] = 2, ["y"] = 5, ["z"] = 0, ["name"] = "default:stone"},
  {["x"] = 2, ["y"] = 5, ["z"] = 12, ["name"] = "default:stone"},
  {["x"] = 3, ["y"] = 5, ["z"] = 0, ["name"] = "default:stone"},
  {["x"] = 3, ["y"] = 5, ["z"] = 12, ["name"] = "default:stone"},
  {["x"] = 4, ["y"] = 5, ["z"] = 0, ["name"] = "default:stone"},
  {["x"] = 4, ["y"] = 5, ["z"] = 12, ["name"] = "default:stone"},
  {["x"] = 5, ["y"] = 5, ["z"] = 0, ["name"] = "default:stone"},
  {["x"] = 5, ["y"] = 5, ["z"] = 12, ["name"] = "default:stone"},
  {["x"] = 6, ["y"] = 5, ["z"] = 0, ["name"] = "default:stone"},
  {["x"] = 6, ["y"] = 5, ["z"] = 2, ["name"] = "default:wood"},
  {["x"] = 6, ["y"] = 5, ["z"] = 12, ["name"] = "default:stone"},
  {["x"] = 7, ["y"] = 5, ["z"] = 0, ["name"] = "default:stone"},
  {["x"] = 7, ["y"] = 5, ["z"] = 12, ["name"] = "default:stone"},
  {["x"] = 8, ["y"] = 5, ["z"] = 0, ["name"] = "default:stone"},
  {["x"] = 8, ["y"] = 5, ["z"] = 12, ["name"] = "default:stone"},
  {["x"] = 9, ["y"] = 5, ["z"] = 0, ["name"] = "default:stone"},
  {["x"] = 9, ["y"] = 5, ["z"] = 12, ["name"] = "default:stone"},
  {["x"] = 10, ["y"] = 5, ["z"] = 0, ["name"] = "default:stone"},
  {["x"] = 10, ["y"] = 5, ["z"] = 12, ["name"] = "default:stone"},
  {["x"] = 11, ["y"] = 5, ["z"] = 0, ["name"] = "default:stone"},
  {["x"] = 11, ["y"] = 5, ["z"] = 1, ["name"] = "default:stone"},
  {["x"] = 11, ["y"] = 5, ["z"] = 11, ["name"] = "default:stone"},
  {["x"] = 11, ["y"] = 5, ["z"] = 12, ["name"] = "default:stone"},
  {["x"] = 12, ["y"] = 5, ["z"] = 0, ["name"] = "default:stone"},
  {["x"] = 12, ["y"] = 5, ["z"] = 1, ["name"] = "default:stone"},
  {["x"] = 12, ["y"] = 5, ["z"] = 2, ["name"] = "default:stone"},
  {["x"] = 12, ["y"] = 5, ["z"] = 3, ["name"] = "default:stone"},
  {["x"] = 12, ["y"] = 5, ["z"] = 4, ["name"] = "default:stone"},
  {["x"] = 12, ["y"] = 5, ["z"] = 5, ["name"] = "default:stone"},
  {["x"] = 12, ["y"] = 5, ["z"] = 6, ["name"] = "default:stone"},
  {["x"] = 12, ["y"] = 5, ["z"] = 7, ["name"] = "default:stone"},
  {["x"] = 12, ["y"] = 5, ["z"] = 8, ["name"] = "default:stone"},
  {["x"] = 12, ["y"] = 5, ["z"] = 9, ["name"] = "default:stone"},
  {["x"] = 12, ["y"] = 5, ["z"] = 10, ["name"] = "default:stone"},
  {["x"] = 12, ["y"] = 5, ["z"] = 11, ["name"] = "default:stone"},
  {["x"] = 12, ["y"] = 5, ["z"] = 12, ["name"] = "default:stone"},
  {["x"] = 0, ["y"] = 6, ["z"] = 0, ["name"] = "default:stone"},
  {["x"] = 0, ["y"] = 6, ["z"] = 1, ["name"] = "default:stone"},
  {["x"] = 0, ["y"] = 6, ["z"] = 2, ["name"] = "default:stone"},
  {["x"] = 0, ["y"] = 6, ["z"] = 3, ["name"] = "default:stone"},
  {["x"] = 0, ["y"] = 6, ["z"] = 4, ["name"] = "default:stone"},
  {["x"] = 0, ["y"] = 6, ["z"] = 5, ["name"] = "default:stone"},
  {["x"] = 0, ["y"] = 6, ["z"] = 6, ["name"] = "default:stone"},
  {["x"] = 0, ["y"] = 6, ["z"] = 7, ["name"] = "default:stone"},
  {["x"] = 0, ["y"] = 6, ["z"] = 8, ["name"] = "default:stone"},
  {["x"] = 0, ["y"] = 6, ["z"] = 9, ["name"] = "default:stone"},
  {["x"] = 0, ["y"] = 6, ["z"] = 10, ["name"] = "default:stone"},
  {["x"] = 0, ["y"] = 6, ["z"] = 11, ["name"] = "default:stone"},
  {["x"] = 0, ["y"] = 6, ["z"] = 12, ["name"] = "default:stone"},
  {["x"] = 1, ["y"] = 6, ["z"] = 0, ["name"] = "default:stone"},
  {["x"] = 1, ["y"] = 6, ["z"] = 1, ["name"] = "default:stone"},
  {["x"] = 1, ["y"] = 6, ["z"] = 6, ["name"] = "default:ladder_wood"},
  {["x"] = 1, ["y"] = 6, ["z"] = 11, ["name"] = "default:stone"},
  {["x"] = 1, ["y"] = 6, ["z"] = 12, ["name"] = "default:stone"},
  {["x"] = 2, ["y"] = 6, ["z"] = 0, ["name"] = "default:stone"},
  {["x"] = 2, ["y"] = 6, ["z"] = 12, ["name"] = "default:stone"},
  {["x"] = 3, ["y"] = 6, ["z"] = 0, ["name"] = "default:stone"},
  {["x"] = 3, ["y"] = 6, ["z"] = 12, ["name"] = "default:stone"},
  {["x"] = 4, ["y"] = 6, ["z"] = 0, ["name"] = "default:stone"},
  {["x"] = 4, ["y"] = 6, ["z"] = 12, ["name"] = "default:stone"},
  {["x"] = 5, ["y"] = 6, ["z"] = 0, ["name"] = "default:stone"},
  {["x"] = 5, ["y"] = 6, ["z"] = 12, ["name"] = "default:stone"},
  {["x"] = 6, ["y"] = 6, ["z"] = 0, ["name"] = "default:stone"},
  {["x"] = 6, ["y"] = 6, ["z"] = 12, ["name"] = "default:stone"},
  {["x"] = 7, ["y"] = 6, ["z"] = 0, ["name"] = "default:stone"},
  {["x"] = 7, ["y"] = 6, ["z"] = 2, ["name"] = "default:wood"},
  {["x"] = 7, ["y"] = 6, ["z"] = 12, ["name"] = "default:stone"},
  {["x"] = 8, ["y"] = 6, ["z"] = 0, ["name"] = "default:stone"},
  {["x"] = 8, ["y"] = 6, ["z"] = 12, ["name"] = "default:stone"},
  {["x"] = 9, ["y"] = 6, ["z"] = 0, ["name"] = "default:stone"},
  {["x"] = 9, ["y"] = 6, ["z"] = 12, ["name"] = "default:stone"},
  {["x"] = 10, ["y"] = 6, ["z"] = 0, ["name"] = "default:stone"},
  {["x"] = 10, ["y"] = 6, ["z"] = 12, ["name"] = "default:stone"},
  {["x"] = 11, ["y"] = 6, ["z"] = 0, ["name"] = "default:stone"},
  {["x"] = 11, ["y"] = 6, ["z"] = 1, ["name"] = "default:stone"},
  {["x"] = 11, ["y"] = 6, ["z"] = 11, ["name"] = "default:stone"},
  {["x"] = 11, ["y"] = 6, ["z"] = 12, ["name"] = "default:stone"},
  {["x"] = 12, ["y"] = 6, ["z"] = 0, ["name"] = "default:stone"},
  {["x"] = 12, ["y"] = 6, ["z"] = 1, ["name"] = "default:stone"},
  {["x"] = 12, ["y"] = 6, ["z"] = 2, ["name"] = "default:stone"},
  {["x"] = 12, ["y"] = 6, ["z"] = 3, ["name"] = "default:stone"},
  {["x"] = 12, ["y"] = 6, ["z"] = 4, ["name"] = "default:stone"},
  {["x"] = 12, ["y"] = 6, ["z"] = 5, ["name"] = "default:stone"},
  {["x"] = 12, ["y"] = 6, ["z"] = 6, ["name"] = "default:stone"},
  {["x"] = 12, ["y"] = 6, ["z"] = 7, ["name"] = "default:stone"},
  {["x"] = 12, ["y"] = 6, ["z"] = 8, ["name"] = "default:stone"},
  {["x"] = 12, ["y"] = 6, ["z"] = 9, ["name"] = "default:stone"},
  {["x"] = 12, ["y"] = 6, ["z"] = 10, ["name"] = "default:stone"},
  {["x"] = 12, ["y"] = 6, ["z"] = 11, ["name"] = "default:stone"},
  {["x"] = 12, ["y"] = 6, ["z"] = 12, ["name"] = "default:stone"},
  {["x"] = 0, ["y"] = 7, ["z"] = 0, ["name"] = "default:stone"},
  {["x"] = 0, ["y"] = 7, ["z"] = 1, ["name"] = "default:stone"},
  {["x"] = 0, ["y"] = 7, ["z"] = 2, ["name"] = "default:stone"},
  {["x"] = 0, ["y"] = 7, ["z"] = 4, ["name"] = "default:stone"},
  {["x"] = 0, ["y"] = 7, ["z"] = 6, ["name"] = "default:stone"},
  {["x"] = 0, ["y"] = 7, ["z"] = 8, ["name"] = "default:stone"},
  {["x"] = 0, ["y"] = 7, ["z"] = 10, ["name"] = "default:stone"},
  {["x"] = 0, ["y"] = 7, ["z"] = 11, ["name"] = "default:stone"},
  {["x"] = 0, ["y"] = 7, ["z"] = 12, ["name"] = "default:stone"},
  {["x"] = 1, ["y"] = 7, ["z"] = 0, ["name"] = "default:stone"},
  {["x"] = 1, ["y"] = 7, ["z"] = 1, ["name"] = "default:stone"},
  {["x"] = 1, ["y"] = 7, ["z"] = 1, ["name"] = "default:wood"},
  {["x"] = 1, ["y"] = 7, ["z"] = 2, ["name"] = "default:wood"},
  {["x"] = 1, ["y"] = 7, ["z"] = 3, ["name"] = "default:wood"},
  {["x"] = 1, ["y"] = 7, ["z"] = 4, ["name"] = "default:wood"},
  {["x"] = 1, ["y"] = 7, ["z"] = 5, ["name"] = "default:wood"},
  {["x"] = 1, ["y"] = 7, ["z"] = 6, ["name"] = "default:wood"},
  {["x"] = 1, ["y"] = 7, ["z"] = 6, ["name"] = "default:ladder_wood"},
  {["x"] = 1, ["y"] = 7, ["z"] = 7, ["name"] = "default:wood"},
  {["x"] = 1, ["y"] = 7, ["z"] = 8, ["name"] = "default:wood"},
  {["x"] = 1, ["y"] = 7, ["z"] = 9, ["name"] = "default:wood"},
  {["x"] = 1, ["y"] = 7, ["z"] = 10, ["name"] = "default:wood"},
  {["x"] = 1, ["y"] = 7, ["z"] = 11, ["name"] = "default:stone"},
  {["x"] = 1, ["y"] = 7, ["z"] = 11, ["name"] = "default:wood"},
  {["x"] = 1, ["y"] = 7, ["z"] = 12, ["name"] = "default:stone"},
  {["x"] = 2, ["y"] = 7, ["z"] = 0, ["name"] = "default:stone"},
  {["x"] = 2, ["y"] = 7, ["z"] = 1, ["name"] = "default:wood"},
  {["x"] = 2, ["y"] = 7, ["z"] = 2, ["name"] = "default:wood"},
  {["x"] = 2, ["y"] = 7, ["z"] = 3, ["name"] = "default:wood"},
  {["x"] = 2, ["y"] = 7, ["z"] = 4, ["name"] = "default:wood"},
  {["x"] = 2, ["y"] = 7, ["z"] = 5, ["name"] = "default:wood"},
  {["x"] = 2, ["y"] = 7, ["z"] = 6, ["name"] = "default:wood"},
  {["x"] = 2, ["y"] = 7, ["z"] = 7, ["name"] = "default:wood"},
  {["x"] = 2, ["y"] = 7, ["z"] = 8, ["name"] = "default:wood"},
  {["x"] = 2, ["y"] = 7, ["z"] = 9, ["name"] = "default:wood"},
  {["x"] = 2, ["y"] = 7, ["z"] = 10, ["name"] = "default:wood"},
  {["x"] = 2, ["y"] = 7, ["z"] = 11, ["name"] = "default:wood"},
  {["x"] = 2, ["y"] = 7, ["z"] = 12, ["name"] = "default:stone"},
  {["x"] = 3, ["y"] = 7, ["z"] = 1, ["name"] = "default:wood"},
  {["x"] = 3, ["y"] = 7, ["z"] = 2, ["name"] = "default:wood"},
  {["x"] = 3, ["y"] = 7, ["z"] = 3, ["name"] = "default:wood"},
  {["x"] = 3, ["y"] = 7, ["z"] = 4, ["name"] = "default:wood"},
  {["x"] = 3, ["y"] = 7, ["z"] = 5, ["name"] = "default:wood"},
  {["x"] = 3, ["y"] = 7, ["z"] = 6, ["name"] = "default:wood"},
  {["x"] = 3, ["y"] = 7, ["z"] = 7, ["name"] = "default:wood"},
  {["x"] = 3, ["y"] = 7, ["z"] = 8, ["name"] = "default:wood"},
  {["x"] = 3, ["y"] = 7, ["z"] = 9, ["name"] = "default:wood"},
  {["x"] = 3, ["y"] = 7, ["z"] = 10, ["name"] = "default:wood"},
  {["x"] = 3, ["y"] = 7, ["z"] = 11, ["name"] = "default:wood"},
  {["x"] = 4, ["y"] = 7, ["z"] = 0, ["name"] = "default:stone"},
  {["x"] = 4, ["y"] = 7, ["z"] = 1, ["name"] = "default:wood"},
  {["x"] = 4, ["y"] = 7, ["z"] = 2, ["name"] = "default:wood"},
  {["x"] = 4, ["y"] = 7, ["z"] = 3, ["name"] = "default:wood"},
  {["x"] = 4, ["y"] = 7, ["z"] = 4, ["name"] = "default:wood"},
  {["x"] = 4, ["y"] = 7, ["z"] = 5, ["name"] = "default:wood"},
  {["x"] = 4, ["y"] = 7, ["z"] = 6, ["name"] = "default:wood"},
  {["x"] = 4, ["y"] = 7, ["z"] = 7, ["name"] = "default:wood"},
  {["x"] = 4, ["y"] = 7, ["z"] = 8, ["name"] = "default:wood"},
  {["x"] = 4, ["y"] = 7, ["z"] = 9, ["name"] = "default:wood"},
  {["x"] = 4, ["y"] = 7, ["z"] = 10, ["name"] = "default:wood"},
  {["x"] = 4, ["y"] = 7, ["z"] = 11, ["name"] = "default:wood"},
  {["x"] = 4, ["y"] = 7, ["z"] = 12, ["name"] = "default:stone"},
  {["x"] = 5, ["y"] = 7, ["z"] = 1, ["name"] = "default:wood"},
  {["x"] = 5, ["y"] = 7, ["z"] = 2, ["name"] = "default:wood"},
  {["x"] = 5, ["y"] = 7, ["z"] = 3, ["name"] = "default:wood"},
  {["x"] = 5, ["y"] = 7, ["z"] = 4, ["name"] = "default:wood"},
  {["x"] = 5, ["y"] = 7, ["z"] = 5, ["name"] = "default:wood"},
  {["x"] = 5, ["y"] = 7, ["z"] = 6, ["name"] = "default:wood"},
  {["x"] = 5, ["y"] = 7, ["z"] = 7, ["name"] = "default:wood"},
  {["x"] = 5, ["y"] = 7, ["z"] = 8, ["name"] = "default:wood"},
  {["x"] = 5, ["y"] = 7, ["z"] = 9, ["name"] = "default:wood"},
  {["x"] = 5, ["y"] = 7, ["z"] = 10, ["name"] = "default:wood"},
  {["x"] = 5, ["y"] = 7, ["z"] = 11, ["name"] = "default:wood"},
  {["x"] = 6, ["y"] = 7, ["z"] = 0, ["name"] = "default:stone"},
  {["x"] = 6, ["y"] = 7, ["z"] = 1, ["name"] = "default:wood"},
  {["x"] = 6, ["y"] = 7, ["z"] = 2, ["name"] = "default:wood"},
  {["x"] = 6, ["y"] = 7, ["z"] = 3, ["name"] = "default:wood"},
  {["x"] = 6, ["y"] = 7, ["z"] = 4, ["name"] = "default:wood"},
  {["x"] = 6, ["y"] = 7, ["z"] = 5, ["name"] = "default:wood"},
  {["x"] = 6, ["y"] = 7, ["z"] = 6, ["name"] = "default:wood"},
  {["x"] = 6, ["y"] = 7, ["z"] = 7, ["name"] = "default:wood"},
  {["x"] = 6, ["y"] = 7, ["z"] = 8, ["name"] = "default:wood"},
  {["x"] = 6, ["y"] = 7, ["z"] = 9, ["name"] = "default:wood"},
  {["x"] = 6, ["y"] = 7, ["z"] = 10, ["name"] = "default:wood"},
  {["x"] = 6, ["y"] = 7, ["z"] = 11, ["name"] = "default:wood"},
  {["x"] = 6, ["y"] = 7, ["z"] = 12, ["name"] = "default:stone"},
  {["x"] = 7, ["y"] = 7, ["z"] = 1, ["name"] = "default:wood"},
  {["x"] = 7, ["y"] = 7, ["z"] = 2, ["name"] = "default:wood"},
  {["x"] = 7, ["y"] = 7, ["z"] = 3, ["name"] = "default:wood"},
  {["x"] = 7, ["y"] = 7, ["z"] = 4, ["name"] = "default:wood"},
  {["x"] = 7, ["y"] = 7, ["z"] = 5, ["name"] = "default:wood"},
  {["x"] = 7, ["y"] = 7, ["z"] = 6, ["name"] = "default:wood"},
  {["x"] = 7, ["y"] = 7, ["z"] = 7, ["name"] = "default:wood"},
  {["x"] = 7, ["y"] = 7, ["z"] = 8, ["name"] = "default:wood"},
  {["x"] = 7, ["y"] = 7, ["z"] = 9, ["name"] = "default:wood"},
  {["x"] = 7, ["y"] = 7, ["z"] = 10, ["name"] = "default:wood"},
  {["x"] = 7, ["y"] = 7, ["z"] = 11, ["name"] = "default:wood"},
  {["x"] = 8, ["y"] = 7, ["z"] = 0, ["name"] = "default:stone"},
  {["x"] = 8, ["y"] = 7, ["z"] = 1, ["name"] = "default:wood"},
  {["x"] = 8, ["y"] = 7, ["z"] = 2, ["name"] = "default:wood"},
  {["x"] = 8, ["y"] = 7, ["z"] = 3, ["name"] = "default:wood"},
  {["x"] = 8, ["y"] = 7, ["z"] = 4, ["name"] = "default:wood"},
  {["x"] = 8, ["y"] = 7, ["z"] = 5, ["name"] = "default:wood"},
  {["x"] = 8, ["y"] = 7, ["z"] = 6, ["name"] = "default:wood"},
  {["x"] = 8, ["y"] = 7, ["z"] = 7, ["name"] = "default:wood"},
  {["x"] = 8, ["y"] = 7, ["z"] = 8, ["name"] = "default:wood"},
  {["x"] = 8, ["y"] = 7, ["z"] = 9, ["name"] = "default:wood"},
  {["x"] = 8, ["y"] = 7, ["z"] = 10, ["name"] = "default:wood"},
  {["x"] = 8, ["y"] = 7, ["z"] = 11, ["name"] = "default:wood"},
  {["x"] = 8, ["y"] = 7, ["z"] = 12, ["name"] = "default:stone"},
  {["x"] = 9, ["y"] = 7, ["z"] = 1, ["name"] = "default:wood"},
  {["x"] = 9, ["y"] = 7, ["z"] = 2, ["name"] = "default:wood"},
  {["x"] = 9, ["y"] = 7, ["z"] = 3, ["name"] = "default:wood"},
  {["x"] = 9, ["y"] = 7, ["z"] = 4, ["name"] = "default:wood"},
  {["x"] = 9, ["y"] = 7, ["z"] = 5, ["name"] = "default:wood"},
  {["x"] = 9, ["y"] = 7, ["z"] = 6, ["name"] = "default:wood"},
  {["x"] = 9, ["y"] = 7, ["z"] = 7, ["name"] = "default:wood"},
  {["x"] = 9, ["y"] = 7, ["z"] = 8, ["name"] = "default:wood"},
  {["x"] = 9, ["y"] = 7, ["z"] = 9, ["name"] = "default:wood"},
  {["x"] = 9, ["y"] = 7, ["z"] = 10, ["name"] = "default:wood"},
  {["x"] = 9, ["y"] = 7, ["z"] = 11, ["name"] = "default:wood"},
  {["x"] = 10, ["y"] = 7, ["z"] = 0, ["name"] = "default:stone"},
  {["x"] = 10, ["y"] = 7, ["z"] = 1, ["name"] = "default:wood"},
  {["x"] = 10, ["y"] = 7, ["z"] = 2, ["name"] = "default:wood"},
  {["x"] = 10, ["y"] = 7, ["z"] = 3, ["name"] = "default:wood"},
  {["x"] = 10, ["y"] = 7, ["z"] = 4, ["name"] = "default:wood"},
  {["x"] = 10, ["y"] = 7, ["z"] = 5, ["name"] = "default:wood"},
  {["x"] = 10, ["y"] = 7, ["z"] = 6, ["name"] = "default:wood"},
  {["x"] = 10, ["y"] = 7, ["z"] = 7, ["name"] = "default:wood"},
  {["x"] = 10, ["y"] = 7, ["z"] = 8, ["name"] = "default:wood"},
  {["x"] = 10, ["y"] = 7, ["z"] = 9, ["name"] = "default:wood"},
  {["x"] = 10, ["y"] = 7, ["z"] = 10, ["name"] = "default:wood"},
  {["x"] = 10, ["y"] = 7, ["z"] = 11, ["name"] = "default:wood"},
  {["x"] = 10, ["y"] = 7, ["z"] = 12, ["name"] = "default:stone"},
  {["x"] = 11, ["y"] = 7, ["z"] = 0, ["name"] = "default:stone"},
  {["x"] = 11, ["y"] = 7, ["z"] = 1, ["name"] = "default:stone"},
  {["x"] = 11, ["y"] = 7, ["z"] = 1, ["name"] = "default:wood"},
  {["x"] = 11, ["y"] = 7, ["z"] = 2, ["name"] = "default:wood"},
  {["x"] = 11, ["y"] = 7, ["z"] = 3, ["name"] = "default:wood"},
  {["x"] = 11, ["y"] = 7, ["z"] = 4, ["name"] = "default:wood"},
  {["x"] = 11, ["y"] = 7, ["z"] = 5, ["name"] = "default:wood"},
  {["x"] = 11, ["y"] = 7, ["z"] = 6, ["name"] = "default:wood"},
  {["x"] = 11, ["y"] = 7, ["z"] = 7, ["name"] = "default:wood"},
  {["x"] = 11, ["y"] = 7, ["z"] = 8, ["name"] = "default:wood"},
  {["x"] = 11, ["y"] = 7, ["z"] = 9, ["name"] = "default:wood"},
  {["x"] = 11, ["y"] = 7, ["z"] = 10, ["name"] = "default:wood"},
  {["x"] = 11, ["y"] = 7, ["z"] = 11, ["name"] = "default:stone"},
  {["x"] = 11, ["y"] = 7, ["z"] = 11, ["name"] = "default:wood"},
  {["x"] = 11, ["y"] = 7, ["z"] = 12, ["name"] = "default:stone"},
  {["x"] = 12, ["y"] = 7, ["z"] = 0, ["name"] = "default:stone"},
  {["x"] = 12, ["y"] = 7, ["z"] = 1, ["name"] = "default:stone"},
  {["x"] = 12, ["y"] = 7, ["z"] = 2, ["name"] = "default:stone"},
  {["x"] = 12, ["y"] = 7, ["z"] = 4, ["name"] = "default:stone"},
  {["x"] = 12, ["y"] = 7, ["z"] = 6, ["name"] = "default:stone"},
  {["x"] = 12, ["y"] = 7, ["z"] = 8, ["name"] = "default:stone"},
  {["x"] = 12, ["y"] = 7, ["z"] = 10, ["name"] = "default:stone"},
  {["x"] = 12, ["y"] = 7, ["z"] = 11, ["name"] = "default:stone"},
  {["x"] = 12, ["y"] = 7, ["z"] = 12, ["name"] = "default:stone"},
  {["x"] = 0, ["y"] = 8, ["z"] = 0, ["name"] = "default:stone"},
  {["x"] = 0, ["y"] = 8, ["z"] = 1, ["name"] = "default:stone"},
  {["x"] = 0, ["y"] = 8, ["z"] = 11, ["name"] = "default:stone"},
  {["x"] = 0, ["y"] = 8, ["z"] = 12, ["name"] = "default:stone"},
  {["x"] = 1, ["y"] = 8, ["z"] = 0, ["name"] = "default:stone"},
  {["x"] = 1, ["y"] = 8, ["z"] = 1, ["name"] = "default:stone"},
  {["x"] = 1, ["y"] = 8, ["z"] = 11, ["name"] = "default:stone"},
  {["x"] = 1, ["y"] = 8, ["z"] = 12, ["name"] = "default:stone"},
  {["x"] = 11, ["y"] = 8, ["z"] = 0, ["name"] = "default:stone"},
  {["x"] = 11, ["y"] = 8, ["z"] = 1, ["name"] = "default:stone"},
  {["x"] = 11, ["y"] = 8, ["z"] = 11, ["name"] = "default:stone"},
  {["x"] = 11, ["y"] = 8, ["z"] = 12, ["name"] = "default:stone"},
  {["x"] = 12, ["y"] = 8, ["z"] = 0, ["name"] = "default:stone"},
  {["x"] = 12, ["y"] = 8, ["z"] = 1, ["name"] = "default:stone"},
  {["x"] = 12, ["y"] = 8, ["z"] = 11, ["name"] = "default:stone"},
  {["x"] = 12, ["y"] = 8, ["z"] = 12, ["name"] = "default:stone"},
  {["x"] = 0, ["y"] = 9, ["z"] = 0, ["name"] = "default:stone"},
  {["x"] = 0, ["y"] = 9, ["z"] = 1, ["name"] = "default:stone"},
  {["x"] = 0, ["y"] = 9, ["z"] = 11, ["name"] = "default:stone"},
  {["x"] = 0, ["y"] = 9, ["z"] = 12, ["name"] = "default:stone"},
  {["x"] = 1, ["y"] = 9, ["z"] = 0, ["name"] = "default:stone"},
  {["x"] = 1, ["y"] = 9, ["z"] = 1, ["name"] = "default:stone"},
  {["x"] = 1, ["y"] = 9, ["z"] = 11, ["name"] = "default:stone"},
  {["x"] = 1, ["y"] = 9, ["z"] = 12, ["name"] = "default:stone"},
  {["x"] = 11, ["y"] = 9, ["z"] = 0, ["name"] = "default:stone"},
  {["x"] = 11, ["y"] = 9, ["z"] = 1, ["name"] = "default:stone"},
  {["x"] = 11, ["y"] = 9, ["z"] = 11, ["name"] = "default:stone"},
  {["x"] = 11, ["y"] = 9, ["z"] = 12, ["name"] = "default:stone"},
  {["x"] = 12, ["y"] = 9, ["z"] = 0, ["name"] = "default:stone"},
  {["x"] = 12, ["y"] = 9, ["z"] = 1, ["name"] = "default:stone"},
  {["x"] = 12, ["y"] = 9, ["z"] = 11, ["name"] = "default:stone"},
  {["x"] = 12, ["y"] = 9, ["z"] = 12, ["name"] = "default:stone"}
}
