return {
  {["x"] = 0, ["y"] = 0, ["z"] = 0, ["name"] = "default:wood"},
  {["x"] = 0, ["y"] = 0, ["z"] = 1, ["name"] = "default:wood"},
  {["x"] = 0, ["y"] = 0, ["z"] = 2, ["name"] = "default:wood"},
  {["x"] = 0, ["y"] = 0, ["z"] = 3, ["name"] = "default:wood"},
  {["x"] = 0, ["y"] = 0, ["z"] = 4, ["name"] = "default:wood"},
  {["x"] = 1, ["y"] = 0, ["z"] = 0, ["name"] = "default:wood"},
  {["x"] = 1, ["y"] = 0, ["z"] = 1, ["name"] = "default:wood"},
  {["x"] = 1, ["y"] = 0, ["z"] = 2, ["name"] = "default:wood"},
  {["x"] = 1, ["y"] = 0, ["z"] = 3, ["name"] = "default:wood"},
  {["x"] = 1, ["y"] = 0, ["z"] = 4, ["name"] = "default:wood"},
  {["x"] = 2, ["y"] = 0, ["z"] = 0, ["name"] = "default:wood"},
  {["x"] = 2, ["y"] = 0, ["z"] = 1, ["name"] = "default:wood"},
  {["x"] = 2, ["y"] = 0, ["z"] = 2, ["name"] = "default:wood"},
  {["x"] = 2, ["y"] = 0, ["z"] = 3, ["name"] = "default:wood"},
  {["x"] = 2, ["y"] = 0, ["z"] = 4, ["name"] = "default:wood"},
  {["x"] = 3, ["y"] = 0, ["z"] = 0, ["name"] = "default:wood"},
  {["x"] = 3, ["y"] = 0, ["z"] = 1, ["name"] = "default:wood"},
  {["x"] = 3, ["y"] = 0, ["z"] = 2, ["name"] = "default:wood"},
  {["x"] = 3, ["y"] = 0, ["z"] = 3, ["name"] = "default:wood"},
  {["x"] = 3, ["y"] = 0, ["z"] = 4, ["name"] = "default:wood"},
  {["x"] = 4, ["y"] = 0, ["z"] = 0, ["name"] = "default:wood"},
  {["x"] = 4, ["y"] = 0, ["z"] = 1, ["name"] = "default:wood"},
  {["x"] = 4, ["y"] = 0, ["z"] = 2, ["name"] = "default:wood"},
  {["x"] = 4, ["y"] = 0, ["z"] = 3, ["name"] = "default:wood"},
  {["x"] = 4, ["y"] = 0, ["z"] = 4, ["name"] = "default:wood"},
  {["x"] = 0, ["y"] = 1, ["z"] = 0, ["name"] = "default:wood"},
  {["x"] = 0, ["y"] = 1, ["z"] = 1, ["name"] = "default:wood"},
  {["x"] = 0, ["y"] = 1, ["z"] = 2, ["name"] = "default:wood"},
  {["x"] = 0, ["y"] = 1, ["z"] = 3, ["name"] = "default:wood"},
  {["x"] = 0, ["y"] = 1, ["z"] = 4, ["name"] = "default:wood"},
  {["x"] = 1, ["y"] = 1, ["z"] = 0, ["name"] = "default:wood"},
  {["x"] = 1, ["y"] = 1, ["z"] = 4, ["name"] = "default:wood"},
  {["x"] = 2, ["y"] = 1, ["z"] = 4, ["name"] = "default:wood"},
  {["x"] = 3, ["y"] = 1, ["z"] = 0, ["name"] = "default:wood"},
  {["x"] = 3, ["y"] = 1, ["z"] = 4, ["name"] = "default:wood"},
  {["x"] = 4, ["y"] = 1, ["z"] = 0, ["name"] = "default:wood"},
  {["x"] = 4, ["y"] = 1, ["z"] = 1, ["name"] = "default:wood"},
  {["x"] = 4, ["y"] = 1, ["z"] = 2, ["name"] = "default:wood"},
  {["x"] = 4, ["y"] = 1, ["z"] = 3, ["name"] = "default:wood"},
  {["x"] = 4, ["y"] = 1, ["z"] = 4, ["name"] = "default:wood"},
  {["x"] = 0, ["y"] = 2, ["z"] = 0, ["name"] = "default:wood"},
  {["x"] = 0, ["y"] = 2, ["z"] = 1, ["name"] = "default:wood"},
  {["x"] = 0, ["y"] = 2, ["z"] = 2, ["name"] = "default:wood"},
  {["x"] = 0, ["y"] = 2, ["z"] = 3, ["name"] = "default:wood"},
  {["x"] = 0, ["y"] = 2, ["z"] = 4, ["name"] = "default:wood"},
  {["x"] = 1, ["y"] = 2, ["z"] = 0, ["name"] = "default:wood"},
  {["x"] = 1, ["y"] = 2, ["z"] = 4, ["name"] = "default:wood"},
  {["x"] = 2, ["y"] = 2, ["z"] = 4, ["name"] = "default:wood"},
  {["x"] = 3, ["y"] = 2, ["z"] = 0, ["name"] = "default:wood"},
  {["x"] = 3, ["y"] = 2, ["z"] = 4, ["name"] = "default:wood"},
  {["x"] = 4, ["y"] = 2, ["z"] = 0, ["name"] = "default:wood"},
  {["x"] = 4, ["y"] = 2, ["z"] = 1, ["name"] = "default:wood"},
  {["x"] = 4, ["y"] = 2, ["z"] = 2, ["name"] = "default:wood"},
  {["x"] = 4, ["y"] = 2, ["z"] = 3, ["name"] = "default:wood"},
  {["x"] = 4, ["y"] = 2, ["z"] = 4, ["name"] = "default:wood"},
  {["x"] = 0, ["y"] = 3, ["z"] = 0, ["name"] = "default:wood"},
  {["x"] = 0, ["y"] = 3, ["z"] = 1, ["name"] = "default:wood"},
  {["x"] = 0, ["y"] = 3, ["z"] = 2, ["name"] = "default:wood"},
  {["x"] = 0, ["y"] = 3, ["z"] = 3, ["name"] = "default:wood"},
  {["x"] = 0, ["y"] = 3, ["z"] = 4, ["name"] = "default:wood"},
  {["x"] = 1, ["y"] = 3, ["z"] = 0, ["name"] = "default:wood"},
  {["x"] = 1, ["y"] = 3, ["z"] = 4, ["name"] = "default:wood"},
  {["x"] = 2, ["y"] = 3, ["z"] = 0, ["name"] = "default:wood"},
  {["x"] = 2, ["y"] = 3, ["z"] = 4, ["name"] = "default:wood"},
  {["x"] = 3, ["y"] = 3, ["z"] = 0, ["name"] = "default:wood"},
  {["x"] = 3, ["y"] = 3, ["z"] = 4, ["name"] = "default:wood"},
  {["x"] = 4, ["y"] = 3, ["z"] = 0, ["name"] = "default:wood"},
  {["x"] = 4, ["y"] = 3, ["z"] = 1, ["name"] = "default:wood"},
  {["x"] = 4, ["y"] = 3, ["z"] = 2, ["name"] = "default:wood"},
  {["x"] = 4, ["y"] = 3, ["z"] = 3, ["name"] = "default:wood"},
  {["x"] = 4, ["y"] = 3, ["z"] = 4, ["name"] = "default:wood"},
  {["x"] = 0, ["y"] = 4, ["z"] = 0, ["name"] = "default:wood"},
  {["x"] = 0, ["y"] = 4, ["z"] = 1, ["name"] = "default:wood"},
  {["x"] = 0, ["y"] = 4, ["z"] = 2, ["name"] = "default:wood"},
  {["x"] = 0, ["y"] = 4, ["z"] = 3, ["name"] = "default:wood"},
  {["x"] = 0, ["y"] = 4, ["z"] = 4, ["name"] = "default:wood"},
  {["x"] = 1, ["y"] = 4, ["z"] = 0, ["name"] = "default:wood"},
  {["x"] = 1, ["y"] = 4, ["z"] = 4, ["name"] = "default:wood"},
  {["x"] = 2, ["y"] = 4, ["z"] = 0, ["name"] = "default:wood"},
  {["x"] = 2, ["y"] = 4, ["z"] = 4, ["name"] = "default:wood"},
  {["x"] = 3, ["y"] = 4, ["z"] = 0, ["name"] = "default:wood"},
  {["x"] = 3, ["y"] = 4, ["z"] = 4, ["name"] = "default:wood"},
  {["x"] = 4, ["y"] = 4, ["z"] = 0, ["name"] = "default:wood"},
  {["x"] = 4, ["y"] = 4, ["z"] = 1, ["name"] = "default:wood"},
  {["x"] = 4, ["y"] = 4, ["z"] = 2, ["name"] = "default:wood"},
  {["x"] = 4, ["y"] = 4, ["z"] = 3, ["name"] = "default:wood"},
  {["x"] = 4, ["y"] = 4, ["z"] = 4, ["name"] = "default:wood"},
  {["x"] = 0, ["y"] = 5, ["z"] = 0, ["name"] = "default:wood"},
  {["x"] = 0, ["y"] = 5, ["z"] = 1, ["name"] = "default:wood"},
  {["x"] = 0, ["y"] = 5, ["z"] = 2, ["name"] = "default:wood"},
  {["x"] = 0, ["y"] = 5, ["z"] = 3, ["name"] = "default:wood"},
  {["x"] = 0, ["y"] = 5, ["z"] = 4, ["name"] = "default:wood"},
  {["x"] = 1, ["y"] = 5, ["z"] = 0, ["name"] = "default:wood"},
  {["x"] = 1, ["y"] = 5, ["z"] = 4, ["name"] = "default:wood"},
  {["x"] = 2, ["y"] = 5, ["z"] = 0, ["name"] = "default:wood"},
  {["x"] = 2, ["y"] = 5, ["z"] = 4, ["name"] = "default:wood"},
  {["x"] = 3, ["y"] = 5, ["z"] = 0, ["name"] = "default:wood"},
  {["x"] = 3, ["y"] = 5, ["z"] = 4, ["name"] = "default:wood"},
  {["x"] = 4, ["y"] = 5, ["z"] = 0, ["name"] = "default:wood"},
  {["x"] = 4, ["y"] = 5, ["z"] = 1, ["name"] = "default:wood"},
  {["x"] = 4, ["y"] = 5, ["z"] = 2, ["name"] = "default:wood"},
  {["x"] = 4, ["y"] = 5, ["z"] = 3, ["name"] = "default:wood"},
  {["x"] = 4, ["y"] = 5, ["z"] = 4, ["name"] = "default:wood"},
  {["x"] = 0, ["y"] = 6, ["z"] = 0, ["name"] = "default:wood"},
  {["x"] = 0, ["y"] = 6, ["z"] = 1, ["name"] = "default:wood"},
  {["x"] = 0, ["y"] = 6, ["z"] = 2, ["name"] = "default:wood"},
  {["x"] = 0, ["y"] = 6, ["z"] = 3, ["name"] = "default:wood"},
  {["x"] = 0, ["y"] = 6, ["z"] = 4, ["name"] = "default:wood"},
  {["x"] = 1, ["y"] = 6, ["z"] = 0, ["name"] = "default:wood"},
  {["x"] = 1, ["y"] = 6, ["z"] = 1, ["name"] = "default:wood"},
  {["x"] = 1, ["y"] = 6, ["z"] = 2, ["name"] = "default:wood"},
  {["x"] = 1, ["y"] = 6, ["z"] = 3, ["name"] = "default:wood"},
  {["x"] = 1, ["y"] = 6, ["z"] = 4, ["name"] = "default:wood"},
  {["x"] = 2, ["y"] = 6, ["z"] = 0, ["name"] = "default:wood"},
  {["x"] = 2, ["y"] = 6, ["z"] = 1, ["name"] = "default:wood"},
  {["x"] = 2, ["y"] = 6, ["z"] = 2, ["name"] = "default:wood"},
  {["x"] = 2, ["y"] = 6, ["z"] = 3, ["name"] = "default:wood"},
  {["x"] = 2, ["y"] = 6, ["z"] = 4, ["name"] = "default:wood"},
  {["x"] = 3, ["y"] = 6, ["z"] = 0, ["name"] = "default:wood"},
  {["x"] = 3, ["y"] = 6, ["z"] = 1, ["name"] = "default:wood"},
  {["x"] = 3, ["y"] = 6, ["z"] = 2, ["name"] = "default:wood"},
  {["x"] = 3, ["y"] = 6, ["z"] = 3, ["name"] = "default:wood"},
  {["x"] = 3, ["y"] = 6, ["z"] = 4, ["name"] = "default:wood"},
  {["x"] = 4, ["y"] = 6, ["z"] = 0, ["name"] = "default:wood"},
  {["x"] = 4, ["y"] = 6, ["z"] = 1, ["name"] = "default:wood"},
  {["x"] = 4, ["y"] = 6, ["z"] = 2, ["name"] = "default:wood"},
  {["x"] = 4, ["y"] = 6, ["z"] = 3, ["name"] = "default:wood"},
  {["x"] = 4, ["y"] = 6, ["z"] = 4, ["name"] = "default:wood"},
  {["x"] = 0, ["y"] = 7, ["z"] = 0, ["name"] = "default:fence_wood"},
  {["x"] = 0, ["y"] = 7, ["z"] = 1, ["name"] = "default:fence_wood"},
  {["x"] = 0, ["y"] = 7, ["z"] = 2, ["name"] = "default:fence_wood"},
  {["x"] = 0, ["y"] = 7, ["z"] = 3, ["name"] = "default:fence_wood"},
  {["x"] = 0, ["y"] = 7, ["z"] = 4, ["name"] = "default:fence_wood"},
  {["x"] = 1, ["y"] = 7, ["z"] = 0, ["name"] = "default:fence_wood"},
  {["x"] = 1, ["y"] = 7, ["z"] = 4, ["name"] = "default:fence_wood"},
  {["x"] = 2, ["y"] = 7, ["z"] = 0, ["name"] = "default:fence_wood"},
  {["x"] = 2, ["y"] = 7, ["z"] = 4, ["name"] = "default:fence_wood"},
  {["x"] = 3, ["y"] = 7, ["z"] = 0, ["name"] = "default:fence_wood"},
  {["x"] = 3, ["y"] = 7, ["z"] = 4, ["name"] = "default:fence_wood"},
  {["x"] = 4, ["y"] = 7, ["z"] = 0, ["name"] = "default:fence_wood"},
  {["x"] = 4, ["y"] = 7, ["z"] = 1, ["name"] = "default:fence_wood"},
  {["x"] = 4, ["y"] = 7, ["z"] = 2, ["name"] = "default:fence_wood"},
  {["x"] = 4, ["y"] = 7, ["z"] = 3, ["name"] = "default:fence_wood"},
  {["x"] = 4, ["y"] = 7, ["z"] = 4, ["name"] = "default:fence_wood"}
}
