return {
  {["x"] = 0, ["y"] = 0, ["z"] = 0, ["name"] = "default:wood"},
  {["x"] = 0, ["y"] = 0, ["z"] = 1, ["name"] = "default:wood"},
  {["x"] = 0, ["y"] = 0, ["z"] = 2, ["name"] = "default:wood"},
  {["x"] = 0, ["y"] = 0, ["z"] = 3, ["name"] = "default:wood"},
  {["x"] = 0, ["y"] = 0, ["z"] = 4, ["name"] = "default:wood"},
  {["x"] = 0, ["y"] = 0, ["z"] = 5, ["name"] = "default:wood"},
  {["x"] = 1, ["y"] = 0, ["z"] = 0, ["name"] = "default:wood"},
  {["x"] = 1, ["y"] = 0, ["z"] = 1, ["name"] = "default:wood"},
  {["x"] = 1, ["y"] = 0, ["z"] = 2, ["name"] = "default:wood"},
  {["x"] = 1, ["y"] = 0, ["z"] = 3, ["name"] = "default:wood"},
  {["x"] = 1, ["y"] = 0, ["z"] = 4, ["name"] = "default:wood"},
  {["x"] = 1, ["y"] = 0, ["z"] = 5, ["name"] = "default:wood"},
  {["x"] = 2, ["y"] = 0, ["z"] = 0, ["name"] = "default:wood"},
  {["x"] = 2, ["y"] = 0, ["z"] = 1, ["name"] = "default:wood"},
  {["x"] = 2, ["y"] = 0, ["z"] = 2, ["name"] = "default:wood"},
  {["x"] = 2, ["y"] = 0, ["z"] = 3, ["name"] = "default:wood"},
  {["x"] = 2, ["y"] = 0, ["z"] = 4, ["name"] = "default:wood"},
  {["x"] = 2, ["y"] = 0, ["z"] = 5, ["name"] = "default:wood"},
  {["x"] = 3, ["y"] = 0, ["z"] = 0, ["name"] = "default:wood"},
  {["x"] = 3, ["y"] = 0, ["z"] = 1, ["name"] = "default:wood"},
  {["x"] = 3, ["y"] = 0, ["z"] = 2, ["name"] = "default:wood"},
  {["x"] = 3, ["y"] = 0, ["z"] = 3, ["name"] = "default:wood"},
  {["x"] = 3, ["y"] = 0, ["z"] = 4, ["name"] = "default:wood"},
  {["x"] = 3, ["y"] = 0, ["z"] = 5, ["name"] = "default:wood"},
  {["x"] = 4, ["y"] = 0, ["z"] = 0, ["name"] = "default:wood"},
  {["x"] = 4, ["y"] = 0, ["z"] = 1, ["name"] = "default:wood"},
  {["x"] = 4, ["y"] = 0, ["z"] = 2, ["name"] = "default:wood"},
  {["x"] = 4, ["y"] = 0, ["z"] = 3, ["name"] = "default:wood"},
  {["x"] = 4, ["y"] = 0, ["z"] = 4, ["name"] = "default:wood"},
  {["x"] = 4, ["y"] = 0, ["z"] = 5, ["name"] = "default:wood"},
  {["x"] = 5, ["y"] = 0, ["z"] = 0, ["name"] = "default:wood"},
  {["x"] = 5, ["y"] = 0, ["z"] = 1, ["name"] = "default:wood"},
  {["x"] = 5, ["y"] = 0, ["z"] = 2, ["name"] = "default:wood"},
  {["x"] = 5, ["y"] = 0, ["z"] = 3, ["name"] = "default:wood"},
  {["x"] = 5, ["y"] = 0, ["z"] = 4, ["name"] = "default:wood"},
  {["x"] = 5, ["y"] = 0, ["z"] = 5, ["name"] = "default:wood"},
  {["x"] = 6, ["y"] = 0, ["z"] = 0, ["name"] = "default:wood"},
  {["x"] = 6, ["y"] = 0, ["z"] = 1, ["name"] = "default:wood"},
  {["x"] = 6, ["y"] = 0, ["z"] = 2, ["name"] = "default:wood"},
  {["x"] = 6, ["y"] = 0, ["z"] = 3, ["name"] = "default:wood"},
  {["x"] = 6, ["y"] = 0, ["z"] = 4, ["name"] = "default:wood"},
  {["x"] = 6, ["y"] = 0, ["z"] = 5, ["name"] = "default:wood"},
  {["x"] = 0, ["y"] = 1, ["z"] = 0, ["name"] = "default:wood"},
  {["x"] = 0, ["y"] = 1, ["z"] = 1, ["name"] = "default:wood"},
  {["x"] = 0, ["y"] = 1, ["z"] = 2, ["name"] = "default:wood"},
  {["x"] = 0, ["y"] = 1, ["z"] = 3, ["name"] = "default:wood"},
  {["x"] = 0, ["y"] = 1, ["z"] = 4, ["name"] = "default:wood"},
  {["x"] = 0, ["y"] = 1, ["z"] = 5, ["name"] = "default:wood"},
  {["x"] = 1, ["y"] = 1, ["z"] = 0, ["name"] = "default:wood"},
  {["x"] = 1, ["y"] = 1, ["z"] = 5, ["name"] = "default:wood"},
  {["x"] = 2, ["y"] = 1, ["z"] = 0, ["name"] = "default:wood"},
  {["x"] = 2, ["y"] = 1, ["z"] = 2, ["name"] = "default:chest"},
  {["x"] = 2, ["y"] = 1, ["z"] = 5, ["name"] = "default:wood"},
  {["x"] = 3, ["y"] = 1, ["z"] = 4, ["name"] = "default:torch"},
  {["x"] = 3, ["y"] = 1, ["z"] = 5, ["name"] = "default:wood"},
  {["x"] = 4, ["y"] = 1, ["z"] = 0, ["name"] = "default:wood"},
  {["x"] = 4, ["y"] = 1, ["z"] = 2, ["name"] = "default:chest"},
  {["x"] = 4, ["y"] = 1, ["z"] = 5, ["name"] = "default:wood"},
  {["x"] = 5, ["y"] = 1, ["z"] = 0, ["name"] = "default:wood"},
  {["x"] = 5, ["y"] = 1, ["z"] = 5, ["name"] = "default:wood"},
  {["x"] = 6, ["y"] = 1, ["z"] = 0, ["name"] = "default:wood"},
  {["x"] = 6, ["y"] = 1, ["z"] = 1, ["name"] = "default:wood"},
  {["x"] = 6, ["y"] = 1, ["z"] = 2, ["name"] = "default:wood"},
  {["x"] = 6, ["y"] = 1, ["z"] = 3, ["name"] = "default:wood"},
  {["x"] = 6, ["y"] = 1, ["z"] = 4, ["name"] = "default:wood"},
  {["x"] = 6, ["y"] = 1, ["z"] = 5, ["name"] = "default:wood"},
  {["x"] = 0, ["y"] = 2, ["z"] = 0, ["name"] = "default:wood"},
  {["x"] = 0, ["y"] = 2, ["z"] = 1, ["name"] = "default:wood"},
  {["x"] = 0, ["y"] = 2, ["z"] = 2, ["name"] = "default:wood"},
  {["x"] = 0, ["y"] = 2, ["z"] = 3, ["name"] = "default:wood"},
  {["x"] = 0, ["y"] = 2, ["z"] = 4, ["name"] = "default:wood"},
  {["x"] = 0, ["y"] = 2, ["z"] = 5, ["name"] = "default:wood"},
  {["x"] = 1, ["y"] = 2, ["z"] = 0, ["name"] = "default:wood"},
  {["x"] = 1, ["y"] = 2, ["z"] = 5, ["name"] = "default:wood"},
  {["x"] = 2, ["y"] = 2, ["z"] = 0, ["name"] = "default:wood"},
  {["x"] = 2, ["y"] = 2, ["z"] = 5, ["name"] = "default:wood"},
  {["x"] = 3, ["y"] = 2, ["z"] = 5, ["name"] = "default:wood"},
  {["x"] = 4, ["y"] = 2, ["z"] = 0, ["name"] = "default:wood"},
  {["x"] = 4, ["y"] = 2, ["z"] = 5, ["name"] = "default:wood"},
  {["x"] = 5, ["y"] = 2, ["z"] = 0, ["name"] = "default:wood"},
  {["x"] = 5, ["y"] = 2, ["z"] = 5, ["name"] = "default:wood"},
  {["x"] = 6, ["y"] = 2, ["z"] = 0, ["name"] = "default:wood"},
  {["x"] = 6, ["y"] = 2, ["z"] = 1, ["name"] = "default:wood"},
  {["x"] = 6, ["y"] = 2, ["z"] = 2, ["name"] = "default:wood"},
  {["x"] = 6, ["y"] = 2, ["z"] = 3, ["name"] = "default:wood"},
  {["x"] = 6, ["y"] = 2, ["z"] = 4, ["name"] = "default:wood"},
  {["x"] = 6, ["y"] = 2, ["z"] = 5, ["name"] = "default:wood"},
  {["x"] = 0, ["y"] = 3, ["z"] = 0, ["name"] = "default:wood"},
  {["x"] = 0, ["y"] = 3, ["z"] = 1, ["name"] = "default:wood"},
  {["x"] = 0, ["y"] = 3, ["z"] = 2, ["name"] = "default:wood"},
  {["x"] = 0, ["y"] = 3, ["z"] = 3, ["name"] = "default:wood"},
  {["x"] = 0, ["y"] = 3, ["z"] = 4, ["name"] = "default:wood"},
  {["x"] = 0, ["y"] = 3, ["z"] = 5, ["name"] = "default:wood"},
  {["x"] = 1, ["y"] = 3, ["z"] = 0, ["name"] = "default:wood"},
  {["x"] = 1, ["y"] = 3, ["z"] = 5, ["name"] = "default:wood"},
  {["x"] = 2, ["y"] = 3, ["z"] = 0, ["name"] = "default:wood"},
  {["x"] = 2, ["y"] = 3, ["z"] = 5, ["name"] = "default:wood"},
  {["x"] = 3, ["y"] = 3, ["z"] = 0, ["name"] = "default:wood"},
  {["x"] = 3, ["y"] = 3, ["z"] = 5, ["name"] = "default:wood"},
  {["x"] = 4, ["y"] = 3, ["z"] = 0, ["name"] = "default:wood"},
  {["x"] = 4, ["y"] = 3, ["z"] = 5, ["name"] = "default:wood"},
  {["x"] = 5, ["y"] = 3, ["z"] = 0, ["name"] = "default:wood"},
  {["x"] = 5, ["y"] = 3, ["z"] = 5, ["name"] = "default:wood"},
  {["x"] = 6, ["y"] = 3, ["z"] = 0, ["name"] = "default:wood"},
  {["x"] = 6, ["y"] = 3, ["z"] = 1, ["name"] = "default:wood"},
  {["x"] = 6, ["y"] = 3, ["z"] = 2, ["name"] = "default:wood"},
  {["x"] = 6, ["y"] = 3, ["z"] = 3, ["name"] = "default:wood"},
  {["x"] = 6, ["y"] = 3, ["z"] = 4, ["name"] = "default:wood"},
  {["x"] = 6, ["y"] = 3, ["z"] = 5, ["name"] = "default:wood"},
  {["x"] = 0, ["y"] = 4, ["z"] = 0, ["name"] = "default:wood"},
  {["x"] = 0, ["y"] = 4, ["z"] = 1, ["name"] = "default:wood"},
  {["x"] = 0, ["y"] = 4, ["z"] = 2, ["name"] = "default:wood"},
  {["x"] = 0, ["y"] = 4, ["z"] = 3, ["name"] = "default:wood"},
  {["x"] = 0, ["y"] = 4, ["z"] = 4, ["name"] = "default:wood"},
  {["x"] = 0, ["y"] = 4, ["z"] = 5, ["name"] = "default:wood"},
  {["x"] = 1, ["y"] = 4, ["z"] = 0, ["name"] = "default:wood"},
  {["x"] = 1, ["y"] = 4, ["z"] = 1, ["name"] = "default:wood"},
  {["x"] = 1, ["y"] = 4, ["z"] = 2, ["name"] = "default:wood"},
  {["x"] = 1, ["y"] = 4, ["z"] = 3, ["name"] = "default:wood"},
  {["x"] = 1, ["y"] = 4, ["z"] = 4, ["name"] = "default:wood"},
  {["x"] = 1, ["y"] = 4, ["z"] = 5, ["name"] = "default:wood"},
  {["x"] = 2, ["y"] = 4, ["z"] = 0, ["name"] = "default:wood"},
  {["x"] = 2, ["y"] = 4, ["z"] = 1, ["name"] = "default:wood"},
  {["x"] = 2, ["y"] = 4, ["z"] = 2, ["name"] = "default:wood"},
  {["x"] = 2, ["y"] = 4, ["z"] = 3, ["name"] = "default:wood"},
  {["x"] = 2, ["y"] = 4, ["z"] = 4, ["name"] = "default:wood"},
  {["x"] = 2, ["y"] = 4, ["z"] = 5, ["name"] = "default:wood"},
  {["x"] = 3, ["y"] = 4, ["z"] = 0, ["name"] = "default:wood"},
  {["x"] = 3, ["y"] = 4, ["z"] = 1, ["name"] = "default:wood"},
  {["x"] = 3, ["y"] = 4, ["z"] = 2, ["name"] = "default:wood"},
  {["x"] = 3, ["y"] = 4, ["z"] = 3, ["name"] = "default:wood"},
  {["x"] = 3, ["y"] = 4, ["z"] = 4, ["name"] = "default:wood"},
  {["x"] = 3, ["y"] = 4, ["z"] = 5, ["name"] = "default:wood"},
  {["x"] = 4, ["y"] = 4, ["z"] = 0, ["name"] = "default:wood"},
  {["x"] = 4, ["y"] = 4, ["z"] = 1, ["name"] = "default:wood"},
  {["x"] = 4, ["y"] = 4, ["z"] = 2, ["name"] = "default:wood"},
  {["x"] = 4, ["y"] = 4, ["z"] = 3, ["name"] = "default:wood"},
  {["x"] = 4, ["y"] = 4, ["z"] = 4, ["name"] = "default:wood"},
  {["x"] = 4, ["y"] = 4, ["z"] = 5, ["name"] = "default:wood"},
  {["x"] = 5, ["y"] = 4, ["z"] = 0, ["name"] = "default:wood"},
  {["x"] = 5, ["y"] = 4, ["z"] = 1, ["name"] = "default:wood"},
  {["x"] = 5, ["y"] = 4, ["z"] = 2, ["name"] = "default:wood"},
  {["x"] = 5, ["y"] = 4, ["z"] = 3, ["name"] = "default:wood"},
  {["x"] = 5, ["y"] = 4, ["z"] = 4, ["name"] = "default:wood"},
  {["x"] = 5, ["y"] = 4, ["z"] = 5, ["name"] = "default:wood"},
  {["x"] = 6, ["y"] = 4, ["z"] = 0, ["name"] = "default:wood"},
  {["x"] = 6, ["y"] = 4, ["z"] = 1, ["name"] = "default:wood"},
  {["x"] = 6, ["y"] = 4, ["z"] = 2, ["name"] = "default:wood"},
  {["x"] = 6, ["y"] = 4, ["z"] = 3, ["name"] = "default:wood"},
  {["x"] = 6, ["y"] = 4, ["z"] = 4, ["name"] = "default:wood"},
  {["x"] = 6, ["y"] = 4, ["z"] = 5, ["name"] = "default:wood"}
}
